Workbook

Sheet Uncalibrated
A1: Device Label | B1: Device № | D1: =("№"&B3&" - "&A3) -> №2 - Blue tape | Y1: 0 | Z1: 0 | AA1: 0 | AB1: 0 | AC1: 0 | AD1: 0 | AE1: 0 | AF1: 0 | AG1: 0 | AH1: 0 | AI1: 0 | AJ1: 0 | AK1: 0 | AL1: 0 | AM1: 0 | AN1: 0 | AO1: 0 | AP1: 0
A2: Nothing | B2: 1 | D2: Actual time | E2: Device time | F2: Interval | G2: Time drift (s) | H2: Time elapsed minutes | I2: Time drift per hour (with ms) | J2: Time drift per hour | K2: Average error (with ms) | L2: Average error (s/hr) | M2: Time from start (minutes) | N2: Interval | Y2: 1.531379 | Z2: 104.62448 | AA2: 1.15695 | AB2: 77.997398 | AC2: 1.15695 | AD2: 77.997398 | AE2: 2.188038 | AF2: 83.313543 | AG2: 1.468955 | AH2: 96.34218 | AI2: 1.687075 | AJ2: 100.98856 | AK2: 1.844197 | AL2: 104.73594 | AM2: 1.741891 | AN2: 111.20417 | AO2: 1.250225 | AP2: 87.912491
A3: Blue tape | B3: 2 | D3: 2024-09-12 15:33:39.219130 | E3: 2024-09-12 15:48:02.991899 | F3: [0.219130, 0.235332] | G3: =(DATEVALUE(LEFT(E3, 10))-DATEVALUE(LEFT(D3, 10))) * 86400 + (TIMEVALUE(MID(E3, 12, 8)) - TIMEVALUE(MID(D3, 12, 8))) * 86400 + (VALUE(RIGHT(E3, 6)) - VALUE(RIGHT(D3, 6))) / 1000000 -> 863.77277 | K3: =((MAX(G3:G25)-MIN(G3:G25))/SUM(H4:H25)) * 60 -> 0.84065639 | L3: =((FLOOR(MAX(G3:G25), 1)-FLOOR(MIN(G3:G25), 1))/SUM(H4:H25)) * 60 -> 0.84437163 | M3: 0 | N3: =(MID(F3, 2, 7) + MID(F3, 12, 8)) / 2 -> 0.227231 | Y3: 2.624694 | Z3: 181.4896 | AA3: 2.281858 | AB3: 154.96198 | AC3: 2.281858 | AD3: 154.96198 | AE3: 2.374968 | AF3: 159.5771 | AG3: 2.530329 | AH3: 164.75782 | AI3: 2.84312 | AJ3: 170.56929 | AK3: 3.062964 | AL3: 175.61562 | AM3: 2.905942 | AN3: 184.55156 | AO3: 9.187744 | AP3: 661.0302
A4: ACCZERO PBRC | B4: 3 | D4: 2024-09-12 17:18:16.688028 | E4: 2024-09-12 17:32:41.992176 | F4: [0.688028, 0.703675] | G4: =(DATEVALUE(LEFT(E4, 10))-DATEVALUE(LEFT(D4, 10))) * 86400 + (TIMEVALUE(MID(E4, 12, 8)) - TIMEVALUE(MID(D4, 12, 8))) * 86400 + (VALUE(RIGHT(E4, 6)) - VALUE(RIGHT(D4, 6))) / 1000000 -> 865.30415 | H4: =((DATEVALUE(LEFT(D4,10))-DATEVALUE(LEFT(D3,10)))*86400+(TIMEVALUE(MID(D4,12,8))-TIMEVALUE(MID(D3,12,8)))*86400+(VALUE(RIGHT(D4,6))-VALUE(RIGHT(D3,6)))/1000000)/ 60 -> 104.62448 | I4: =(G4 - G3) / H4 * 60 -> 0.87821453 | J4: =(FLOOR(G4, 1) - FLOOR(G3, 1)) / H4 * 60 -> 1.1469591 | M4: =M3 + H4 -> 104.62448 | N4: =(MID(F4, 2, 7) + MID(F4, 12, 8)) / 2 -> 0.6958475 | Y4: 3.52958 | Z4: 242.8912 | AA4: 3.187752 | AB4: 216.26356 | AC4: 3.187752 | AD4: 216.26356 | AE4: 3.281354 | AF4: 220.96199 | AG4: 3.468865 | AH4: 225.75885 | AI4: 3.905955 | AJ4: 234.30157 | AK4: 4.187898 | AL4: 239.01354 | AM4: 3.874572 | AN4: 245.83543
A5: IMGCOF | B5: 4 | D5: 2024-09-12 18:35:08.594893 | E5: 2024-09-12 18:49:34.992356 | F5: [0.594893, 0.610182] | G5: =(DATEVALUE(LEFT(E5, 10))-DATEVALUE(LEFT(D5, 10))) * 86400 + (TIMEVALUE(MID(E5, 12, 8)) - TIMEVALUE(MID(D5, 12, 8))) * 86400 + (VALUE(RIGHT(E5, 6)) - VALUE(RIGHT(D5, 6))) / 1000000 -> 866.39746 | H5: =((DATEVALUE(LEFT(D5,10))-DATEVALUE(LEFT(D4,10)))*86400+(TIMEVALUE(MID(D5,12,8))-TIMEVALUE(MID(D4,12,8)))*86400+(VALUE(RIGHT(D5,6))-VALUE(RIGHT(D4,6)))/1000000)/ 60 -> 76.865114 | I5: =(G5 - G4) / H5 * 60 -> 0.85342877 | J5: =(FLOOR(G5, 1) - FLOOR(G4, 1)) / H5 * 60 -> 0.78058818 | K5: Average with time set | L5: Average error before measure | M5: =M4 + H5 -> 181.4896 | N5: =(MID(F5, 2, 7) + MID(F5, 12, 8)) / 2 -> 0.602536 | Y5: 7.53135 | Z5: 524.55782 | AA5: 7.312949 | AB5: 498.77813 | AC5: 7.312949 | AD5: 498.77813 | AE5: 7.398495 | AF5: 503.9599 | AG5: 7.781057 | AH5: 508.75364 | AI5: 8.593384 | AJ5: 515.95678 | AK5: 9.093586 | AL5: 522.31512 | AM5: 8.343109 | AN5: 529.59428
A6: ERR15 | B6: 5 | D6: 2024-09-12 19:36:32.691076 | E6: 2024-09-12 19:50:59.993425 | F6: [0.704355, 0.719084] | G6: =(DATEVALUE(LEFT(E6, 10))-DATEVALUE(LEFT(D6, 10))) * 86400 + (TIMEVALUE(MID(E6, 12, 8)) - TIMEVALUE(MID(D6, 12, 8))) * 86400 + (VALUE(RIGHT(E6, 6)) - VALUE(RIGHT(D6, 6))) / 1000000 -> 867.30235 | H6: =((DATEVALUE(LEFT(D6,10))-DATEVALUE(LEFT(D5,10)))*86400+(TIMEVALUE(MID(D6,12,8))-TIMEVALUE(MID(D5,12,8)))*86400+(VALUE(RIGHT(D6,6))-VALUE(RIGHT(D5,6)))/1000000)/ 60 -> 61.401603 | I6: =(G6 - G5) / H6 * 60 -> 0.88423033 | J6: =(FLOOR(G6, 1) - FLOOR(G5, 1)) / H6 * 60 -> 0.97717318 | K6: =(MAX(G3:G24)/(DATEDIF(VALUE(DATE(2000 + MID(B12, 1, 2), MID(B12, 4, 2), MID(B12, 7, 2))),VALUE(MID(D3, 1, 10)),"d")*(60*24)+(TIMEVALUE(MID(D3,12,8))-TIMEVALUE(RIGHT(B12,8))*24*60+MID(D3,21,6)/86400000+MAX(M3:M25)))) * 60 -> 0.86333517 | L6: =(MIN(G3:G24)/(DATEDIF(VALUE(DATE(2000 + MID(B12, 1, 2), MID(B12, 4, 2), MID(B12, 7, 2))),VALUE(MID(D3, 1, 10)),"d")*(60*24)+(TIMEVALUE(MID(D3,12,8))-TIMEVALUE(RIGHT(B12,8))*24*60+MID(D3,21,6)/86400000))) * 60 -> 0.86716409 | M6: =M5 + H6 -> 242.8912 | N6: =(MID(F6, 2, 7) + MID(F6, 12, 8)) / 2 -> 0.711717 | Y6: 14.124964 | Z6: 1142.5813 | AA6: 14.094822 | AB6: 1116.3651 | AC6: 14.094822 | AD6: 1116.3651 | AE6: 14.186932 | AF6: 1122.3302 | AG6: 14.999542 | AH6: 1127.3333 | AI6: 16.593444 | AJ6: 1131.9568 | AK6: 17.437665 | AL6: 1136.4094 | AM6: 15.781117 | AN6: 1143.3703
A7: IMG COR LSU | B7: 6 | D7: 2024-09-13 00:18:12.688373 | E7: 2024-09-13 00:32:43.992492 | F7: [0.688373, 0.703389] | G7: =(DATEVALUE(LEFT(E7, 10))-DATEVALUE(LEFT(D7, 10))) * 86400 + (TIMEVALUE(MID(E7, 12, 8)) - TIMEVALUE(MID(D7, 12, 8))) * 86400 + (VALUE(RIGHT(E7, 6)) - VALUE(RIGHT(D7, 6))) / 1000000 -> 871.30412 | H7: =((DATEVALUE(LEFT(D7,10))-DATEVALUE(LEFT(D6,10)))*86400+(TIMEVALUE(MID(D7,12,8))-TIMEVALUE(MID(D6,12,8)))*86400+(VALUE(RIGHT(D7,6))-VALUE(RIGHT(D6,6)))/1000000)/ 60 -> 281.66662 | I7: =(G7 - G6) / H7 * 60 -> 0.85244818 | J7: =(FLOOR(G7, 1) - FLOOR(G6, 1)) / H7 * 60 -> 0.85207114 | M7: =M6 + H7 -> 524.55782 | N7: =(MID(F7, 2, 7) + MID(F7, 12, 8)) / 2 -> 0.6958795 | Y7: 15.687032 | Z7: 1251.1886 | AA7: 15.62551 | AB7: 1220.4396 | AC7: 15.62551 | AD7: 1220.4396 | AE7: 15.625582 | AF7: 1220.2562 | AG7: 16.405601 | AH7: 1220.8933 | AI7: 18.061904 | AJ7: 1220.1323 | AK7: 18.844353 | AL7: 1217.8193 | AM7: 16.906395 | AN7: 1215.7349
A8: IVAN ERR15 | B8: 7 | D8: 2024-09-13 10:36:14.094765 | E8: 2024-09-13 10:50:51.992498 | F8: [0.094765, 0.109769] | G8: =(DATEVALUE(LEFT(E8, 10))-DATEVALUE(LEFT(D8, 10))) * 86400 + (TIMEVALUE(MID(E8, 12, 8)) - TIMEVALUE(MID(D8, 12, 8))) * 86400 + (VALUE(RIGHT(E8, 6)) - VALUE(RIGHT(D8, 6))) / 1000000 -> 877.89773 | H8: =((DATEVALUE(LEFT(D8,10))-DATEVALUE(LEFT(D7,10)))*86400+(TIMEVALUE(MID(D8,12,8))-TIMEVALUE(MID(D7,12,8)))*86400+(VALUE(RIGHT(D8,6))-VALUE(RIGHT(D7,6)))/1000000)/ 60 -> 618.02344 | I8: =(G8 - G7) / H8 * 60 -> 0.64013242 | J8: =(FLOOR(G8, 1) - FLOOR(G7, 1)) / H8 * 60 -> 0.58250218 | K8: Standard Deviation | M8: =M7 + H8 -> 1142.5813 | N8: =(MID(F8, 2, 7) + MID(F8, 12, 8)) / 2 -> 0.1022645 | Y8: 16.562142 | Z8: 1313.274 | AA8: 16.532012 | AB8: 1282.3578 | AC8: 16.532012 | AD8: 1282.3578 | AE8: 16.562423 | AF8: 1283.424 | AG8: 17.343647 | AH8: 1282.5943 | AI8: 18.936919 | AJ8: 1273.5511 | AK8: 19.811684 | AL8: 1273.2032 | AM8: 17.81169 | AN8: 1274.4198
A9: AIM TRAINING DEVICE | B9: 8 | D9: 2024-09-13 12:24:50.532423 | E9: 2024-09-13 12:39:29.992224 | F9: [0.532423, 0.547974] | G9: =(DATEVALUE(LEFT(E9, 10))-DATEVALUE(LEFT(D9, 10))) * 86400 + (TIMEVALUE(MID(E9, 12, 8)) - TIMEVALUE(MID(D9, 12, 8))) * 86400 + (VALUE(RIGHT(E9, 6)) - VALUE(RIGHT(D9, 6))) / 1000000 -> 879.4598 | H9: =((DATEVALUE(LEFT(D9,10))-DATEVALUE(LEFT(D8,10)))*86400+(TIMEVALUE(MID(D9,12,8))-TIMEVALUE(MID(D8,12,8)))*86400+(VALUE(RIGHT(D9,6))-VALUE(RIGHT(D8,6)))/1000000)/ 60 -> 108.60729 | I9: =(G9 - G8) / H9 * 60 -> 0.86296303 | J9: =(FLOOR(G9, 1) - FLOOR(G8, 1)) / H9 * 60 -> 1.1048982 | K9: =_xlfn.STDEV.P(I4:I24) -> 0.05566086 | M9: =M8 + H9 -> 1251.1886 | N9: =(MID(F9, 2, 7) + MID(F9, 12, 8)) / 2 -> 0.540197 | Y9: 19.625032 | Z9: 1528.2563 | AA9: 19.687984 | AB9: 1497.7552 | AC9: 19.687984 | AD9: 1497.7552 | AE9: 19.719006 | AF9: 1498.9214 | AG9: 20.656142 | AH9: 1499.9891 | AI9: 22.686351 | AJ9: 1500.7719 | AK9: 23.749844 | AL9: 1501.2708 | AM9: 21.406346 | AN9: 1503.2432
A10: Device name | B10: Last time set time | D10: 2024-09-13 13:26:55.657122 | E10: 2024-09-13 13:41:35.992033 | F10: [0.657122, 0.673056] | G10: =(DATEVALUE(LEFT(E10, 10))-DATEVALUE(LEFT(D10, 10))) * 86400 + (TIMEVALUE(MID(E10, 12, 8)) - TIMEVALUE(MID(D10, 12, 8))) * 86400 + (VALUE(RIGHT(E10, 6)) - VALUE(RIGHT(D10, 6))) / 1000000 -> 880.33491 | H10: =((DATEVALUE(LEFT(D10,10))-DATEVALUE(LEFT(D9,10)))*86400+(TIMEVALUE(MID(D10,12,8))-TIMEVALUE(MID(D9,12,8)))*86400+(VALUE(RIGHT(D10,6))-VALUE(RIGHT(D9,6)))/1000000)/ 60 -> 62.085412 | I10: =(G10 - G9) / H10 * 60 -> 0.84571558 | J10: =(FLOOR(G10, 1) - FLOOR(G9, 1)) / H10 * 60 -> 0.9664106 | M10: =M9 + H10 -> 1313.274 | N10: =(MID(F10, 2, 7) + MID(F10, 12, 8)) / 2 -> 0.665088 | Y10: 36.906033 | Z10: 2733.2849 | AA10: 37.312901 | AB10: 2702.0115 | AC10: 37.312901 | AD10: 2702.0115 | AE10: 37.312924 | AF10: 2702.6115 | AG10: 39.031296 | AH10: 2703.0995 | AI10: 42.718568 | AJ10: 2702.8714 | AK10: 44.500026 | AL10: 2702.5083 | AM10: 40.374694 | AN10: 2704.1604
A11: =("№"&B2&" - "&A2) -> №1 - Nothing | B11: Last time set time | D11: 2024-09-13 17:01:54.594733 | E11: 2024-09-13 17:16:37.992534 | F11: [0.594733, 0.609666] | G11: =(DATEVALUE(LEFT(E11, 10))-DATEVALUE(LEFT(D11, 10))) * 86400 + (TIMEVALUE(MID(E11, 12, 8)) - TIMEVALUE(MID(D11, 12, 8))) * 86400 + (VALUE(RIGHT(E11, 6)) - VALUE(RIGHT(D11, 6))) / 1000000 -> 883.3978 | H11: =((DATEVALUE(LEFT(D11,10))-DATEVALUE(LEFT(D10,10)))*86400+(TIMEVALUE(MID(D11,12,8))-TIMEVALUE(MID(D10,12,8)))*86400+(VALUE(RIGHT(D11,6))-VALUE(RIGHT(D10,6)))/1000000)/ 60 -> 214.98229 | I11: =(G11 - G10) / H11 * 60 -> 0.8548304 | J11: =(FLOOR(G11, 1) - FLOOR(G10, 1)) / H11 * 60 -> 0.83727826 | M11: =M10 + H11 -> 1528.2563 | N11: =(MID(F11, 2, 7) + MID(F11, 12, 8)) / 2 -> 0.602198 | Y11: 38.719077 | Z11: 2857.6714 | AA11: 39.156852 | AB11: 2826.0307 | AC11: 39.156852 | AD11: 2826.0307 | AE11: 39.156845 | AF11: 2825.7974 | AG11: 40.906352 | AH11: 2824.3182 | AI11: 44.750053 | AJ11: 2823.5375 | AK11: 46.593969 | AL11: 2821.6234 | AM11: 42.249898 | AN11: 2820.8125
A12: =("№"&B3&" - "&A3) -> №2 - Blue tape | B12: 24-08-01 11:55:18 | D12: 2024-09-14 13:06:56.313628 | E12: 2024-09-14 13:21:56.992430 | F12: [0.313628, 0.328769] | G12: =(DATEVALUE(LEFT(E12, 10))-DATEVALUE(LEFT(D12, 10))) * 86400 + (TIMEVALUE(MID(E12, 12, 8)) - TIMEVALUE(MID(D12, 12, 8))) * 86400 + (VALUE(RIGHT(E12, 6)) - VALUE(RIGHT(D12, 6))) / 1000000 -> 900.6788 | H12: =((DATEVALUE(LEFT(D12,10))-DATEVALUE(LEFT(D11,10)))*86400+(TIMEVALUE(MID(D12,12,8))-TIMEVALUE(MID(D11,12,8)))*86400+(VALUE(RIGHT(D12,6))-VALUE(RIGHT(D11,6)))/1000000)/ 60 -> 1205.0286 | I12: =(G12 - G11) / H12 * 60 -> 0.86044432 | J12: =(FLOOR(G12, 1) - FLOOR(G11, 1)) / H12 * 60 -> 0.84645291 | M12: =M11 + H12 -> 2733.2849 | N12: =(MID(F12, 2, 7) + MID(F12, 12, 8)) / 2 -> 0.3211945 | Y12: 47.562267 | Z12: 3470.9573 | AA12: 48.251094 | AB12: 3444.0792 | AC12: 48.251094 | AD12: 3444.0792 | AE12: 48.218994 | AF12: 3443.1297 | AG12: 50.406141 | AH12: 3443.0266 | AI12: 55.093503 | AJ12: 3443.5318 | AK12: 57.375135 | AL12: 3442.8271 | AM12: 52.093832 | AN12: 3443.4151
A13: =("№"&B4&" - "&A4) -> №3 - ACCZERO PBRC | B13: 24-06-20 17:12:23 | D13: 2024-09-14 15:11:19.500607 | E13: 2024-09-14 15:26:21.992453 | F13: [0.500607, 0.515701] | G13: =(DATEVALUE(LEFT(E13, 10))-DATEVALUE(LEFT(D13, 10))) * 86400 + (TIMEVALUE(MID(E13, 12, 8)) - TIMEVALUE(MID(D13, 12, 8))) * 86400 + (VALUE(RIGHT(E13, 6)) - VALUE(RIGHT(D13, 6))) / 1000000 -> 902.49185 | H13: =((DATEVALUE(LEFT(D13,10))-DATEVALUE(LEFT(D12,10)))*86400+(TIMEVALUE(MID(D13,12,8))-TIMEVALUE(MID(D12,12,8)))*86400+(VALUE(RIGHT(D13,6))-VALUE(RIGHT(D12,6)))/1000000)/ 60 -> 124.38645 | I13: =(G13 - G12) / H13 * 60 -> 0.87455378 | J13: =(FLOOR(G13, 1) - FLOOR(G12, 1)) / H13 * 60 -> 0.96473531 | M13: =M12 + H13 -> 2857.6714 | N13: =(MID(F13, 2, 7) + MID(F13, 12, 8)) / 2 -> 0.5081505 | Y13: 56.781005 | Z13: 4115.6537 | AA13: 57.688608 | AB13: 4089.8052 | AC13: 57.688608 | AD13: 4089.8052 | AE13: 57.750102 | AF13: 4095.9375 | AG13: 60.437551 | AH13: 4101.0927 | AI13: 66.124648 | AJ13: 4106.6479 | AK13: 69.062906 | AL13: 4119.0823 | AM13: 62.905785 | AN13: 4127.0016
A14: =("№"&B5&" - "&A5) -> №4 - IMGCOF | B14: 24-04-22 11:05:09 | D14: 2024-09-15 01:24:36.657774 | E14: 2024-09-15 01:39:47.992810 | F14: [0.673143, 0.688379] | G14: =(DATEVALUE(LEFT(E14, 10))-DATEVALUE(LEFT(D14, 10))) * 86400 + (TIMEVALUE(MID(E14, 12, 8)) - TIMEVALUE(MID(D14, 12, 8))) * 86400 + (VALUE(RIGHT(E14, 6)) - VALUE(RIGHT(D14, 6))) / 1000000 -> 911.33504 | H14: =((DATEVALUE(LEFT(D14,10))-DATEVALUE(LEFT(D13,10)))*86400+(TIMEVALUE(MID(D14,12,8))-TIMEVALUE(MID(D13,12,8)))*86400+(VALUE(RIGHT(D14,6))-VALUE(RIGHT(D13,6)))/1000000)/ 60 -> 613.28595 | I14: =(G14 - G13) / H14 * 60 -> 0.86516151 | J14: =(FLOOR(G14, 1) - FLOOR(G13, 1)) / H14 * 60 -> 0.8805028 | M14: =M13 + H14 -> 3470.9573 | N14: =(MID(F14, 2, 7) + MID(F14, 12, 8)) / 2 -> 0.6807595 | Y14: 65.593768 | Z14: 4725.5234 | AA14: 66.687446 | AB14: 4701.5886 | AC14: 66.687446 | AD14: 4701.5886 | AE14: 66.781311 | AF14: 4708.637 | AG14: 69.875463 | AH14: 4713.8521 | AI14: 76.436951 | AJ14: 4722.1594 | AK14: 79.625177 | AL14: 4726.5396 | AM14: 72.529892 | AN14: 4733.5079
A15: =("№"&B6&" - "&A6) -> №5 - ERR15 | B15: 24-03-27 14:06:13 | D15: 2024-09-15 12:09:18.438620 | E15: 2024-09-15 12:24:38.992394 | F15: [0.438620, 0.453832] | G15: =(DATEVALUE(LEFT(E15, 10))-DATEVALUE(LEFT(D15, 10))) * 86400 + (TIMEVALUE(MID(E15, 12, 8)) - TIMEVALUE(MID(D15, 12, 8))) * 86400 + (VALUE(RIGHT(E15, 6)) - VALUE(RIGHT(D15, 6))) / 1000000 -> 920.55377 | H15: =((DATEVALUE(LEFT(D15,10))-DATEVALUE(LEFT(D14,10)))*86400+(TIMEVALUE(MID(D15,12,8))-TIMEVALUE(MID(D14,12,8)))*86400+(VALUE(RIGHT(D15,6))-VALUE(RIGHT(D14,6)))/1000000)/ 60 -> 644.69635 | I15: =(G15 - G14) / H15 * 60 -> 0.85796093 | J15: =(FLOOR(G15, 1) - FLOOR(G14, 1)) / H15 * 60 -> 0.83760363 | M15: =M14 + H15 -> 4115.6537 | N15: =(MID(F15, 2, 7) + MID(F15, 12, 8)) / 2 -> 0.446226 | Y15: 76.812419 | Z15: 5506.9531 | AA15: 78.031981 | AB15: 5476.4495 | AC15: 78.031981 | AD15: 5476.4495 | AE15: 78.031535 | AF15: 5477.5828 | AG15: 81.562302 | AH15: 5478.2573 | AI15: 89.030972 | AJ15: 5478.3495 | AK15: 92.656444 | AL15: 5478.5057 | AM15: 84.311428 | AN15: 5480.4115
A16: =("№"&B7&" - "&A7) -> №6 - IMG COR LSU | B16: 24-05-27 17:28:36 | D16: 2024-09-15 22:19:10.625739 | E16: 2024-09-15 22:34:39.992276 | F16: [0.640999, 0.656901] | G16: =(DATEVALUE(LEFT(E16, 10))-DATEVALUE(LEFT(D16, 10))) * 86400 + (TIMEVALUE(MID(E16, 12, 8)) - TIMEVALUE(MID(D16, 12, 8))) * 86400 + (VALUE(RIGHT(E16, 6)) - VALUE(RIGHT(D16, 6))) / 1000000 -> 929.36654 | H16: =((DATEVALUE(LEFT(D16,10))-DATEVALUE(LEFT(D15,10)))*86400+(TIMEVALUE(MID(D16,12,8))-TIMEVALUE(MID(D15,12,8)))*86400+(VALUE(RIGHT(D16,6))-VALUE(RIGHT(D15,6)))/1000000)/ 60 -> 609.86979 | I16: =(G16 - G15) / H16 * 60 -> 0.86701423 | J16: =(FLOOR(G16, 1) - FLOOR(G15, 1)) / H16 * 60 -> 0.88543491 | M16: =M15 + H16 -> 4725.5234 | N16: =(MID(F16, 2, 7) + MID(F16, 12, 8)) / 2 -> 0.6489455 | Y16: 122.06078 | Z16: 8650.2323 | AA16: 124.34453 | AB16: 8624.7943 | AC16: 124.34453 | AD16: 8624.7943 | AE16: 124.59409 | AF16: 8649.2234 | AG16: 130.06276 | AH16: 8641.2156 | AI16: 141.84319 | AJ16: 8637.786 | AK16: 147.71906 | AL16: 8653.7547 | AM16: 134.62468 | AN16: 8655.9563
A17: =("№"&B8&" - "&A8) -> №7 - IVAN ERR15 | B17: 24-02-28 16:35:41 | D17: 2024-09-16 11:20:36.406907 | E17: 2024-09-16 11:36:16.992095 | F17: [0.422617, 0.437630] | G17: =(DATEVALUE(LEFT(E17, 10))-DATEVALUE(LEFT(D17, 10))) * 86400 + (TIMEVALUE(MID(E17, 12, 8)) - TIMEVALUE(MID(D17, 12, 8))) * 86400 + (VALUE(RIGHT(E17, 6)) - VALUE(RIGHT(D17, 6))) / 1000000 -> 940.58519 | H17: =((DATEVALUE(LEFT(D17,10))-DATEVALUE(LEFT(D16,10)))*86400+(TIMEVALUE(MID(D17,12,8))-TIMEVALUE(MID(D16,12,8)))*86400+(VALUE(RIGHT(D17,6))-VALUE(RIGHT(D16,6)))/1000000)/ 60 -> 781.42969 | I17: =(G17 - G16) / H17 * 60 -> 0.86139428 | J17: =(FLOOR(G17, 1) - FLOOR(G16, 1)) / H17 * 60 -> 0.84460574 | M17: =M16 + H17 -> 5506.9531 | N17: =(MID(F17, 2, 7) + MID(F17, 12, 8)) / 2 -> 0.43012 | Y17: 141.3752 | Z17: 10090.344 | AA17: 144.06272 | AB17: 10063.982 | AC17: 144.06272 | AD17: 10063.982 | AE17: 144.03119 | AF17: 10069.666 | AG17: 150.62504 | AH17: 10075.956 | AI17: 164.5308 | AJ17: 10081.458 | AK17: 171.15659 | AL17: 10087.897 | AM17: 155.93685 | AN17: 10093.851
A18: =("№"&B9&" - "&A9) -> №8 - AIM TRAINING DEVICE | B18: 24-03-05 12:02:04 | D18: 2024-09-18 15:43:53.160018 | E18: 2024-09-18 16:00:18.993568 | F18: [0.160018, 0.172883] | G18: =(DATEVALUE(LEFT(E18, 10))-DATEVALUE(LEFT(D18, 10))) * 86400 + (TIMEVALUE(MID(E18, 12, 8)) - TIMEVALUE(MID(D18, 12, 8))) * 86400 + (VALUE(RIGHT(E18, 6)) - VALUE(RIGHT(D18, 6))) / 1000000 -> 985.83355 | H18: =((DATEVALUE(LEFT(D18,10))-DATEVALUE(LEFT(D17,10)))*86400+(TIMEVALUE(MID(D18,12,8))-TIMEVALUE(MID(D17,12,8)))*86400+(VALUE(RIGHT(D18,6))-VALUE(RIGHT(D17,6)))/1000000)/ 60 -> 3143.2792 | I18: =(G18 - G17) / H18 * 60 -> 0.86371637 | J18: =(FLOOR(G18, 1) - FLOOR(G17, 1)) / H18 * 60 -> 0.85897555 | M18: =M17 + H18 -> 8650.2323 | N18: =(MID(F18, 2, 7) + MID(F18, 12, 8)) / 2 -> 0.1664465 | AA18: 191.15713 | AB18: 13273.647 | AC18: 191.15713 | AD18: 13273.647 | AE18: 191.09409 | AF18: 13278.798 | AG18: 199.78136 | AH18: 13286.354 | AI18: 218.15605 | AJ18: 13293.864 | AK18: 226.78087 | AL18: 13298.737 | AM18: 206.81183 | AN18: 13305.67
D19: 2024-09-19 15:43:59.844296 | E19: 2024-09-19 16:00:44.992264 | F19: [0.844296, 0.859769] | G19: =(DATEVALUE(LEFT(E19, 10))-DATEVALUE(LEFT(D19, 10))) * 86400 + (TIMEVALUE(MID(E19, 12, 8)) - TIMEVALUE(MID(D19, 12, 8))) * 86400 + (VALUE(RIGHT(E19, 6)) - VALUE(RIGHT(D19, 6))) / 1000000 -> 1005.148 | H19: =((DATEVALUE(LEFT(D19,10))-DATEVALUE(LEFT(D18,10)))*86400+(TIMEVALUE(MID(D19,12,8))-TIMEVALUE(MID(D18,12,8)))*86400+(VALUE(RIGHT(D19,6))-VALUE(RIGHT(D18,6)))/1000000)/ 60 -> 1440.1114 | I19: =(G19 - G18) / H19 * 60 -> 0.80470516 | J19: =(FLOOR(G19, 1) - FLOOR(G18, 1)) / H19 * 60 -> 0.83326887 | M19: =M18 + H19 -> 10090.344 | N19: =(MID(F19, 2, 7) + MID(F19, 12, 8)) / 2 -> 0.8520295 | AA19: 193.68827 | AB19: 13446.755 | AC19: 193.68827 | AD19: 13446.755 | AE19: 193.71883 | AF19: 13456.871 | AG19: 202.40606 | AH19: 13457.777 | AI19: 220.99914 | AJ19: 13464.7 | AK19: 229.71841 | AL19: 13468.788 | AM19: 209.28081 | AN19: 13463.562
A20: Average time drift overall: | P20: Interval average:
A21: =AVERAGE(K3, K27, K51, K75, K99, K123, K147, K181) -> 0.91597471 | P21: =AVERAGE(N3:N185) -> 0.47521439
A23: Average ppm:
A24: =A21 / 3600 * 1000000 -> 254.43742
D25: =("№"&B4&" - "&A4) -> №3 - ACCZERO PBRC
A26: CALM: | B26: CALP: | D26: Actual time | E26: Device time | F26: Interval | G26: Time drift (s) | H26: Time elapsed minutes | I26: Time drift per hour (with ms) | J26: Time drift per hour | K26: Average error (with ms) | L26: Average error (s/hr) | M26: Time from start (minutes)
A27: =IF(A24 > 0, ROUND(A24 / 0.9537, 0), IF(A24 + 488.5 > 0, ROUND((A24 + 488.5) / 0.9537, 0), 0)) -> 267 | B27: =IF(A24 > 0, 0, 1) -> 0 | D27: 2024-09-12 16:02:30.844595 | E27: 2024-09-12 16:36:38.991602 | F27: [0.844595, 0.861392] | G27: =(DATEVALUE(LEFT(E27, 10))-DATEVALUE(LEFT(D27, 10))) * 86400 + (TIMEVALUE(MID(E27, 12, 8)) - TIMEVALUE(MID(D27, 12, 8))) * 86400 + (VALUE(RIGHT(E27, 6)) - VALUE(RIGHT(D27, 6))) / 1000000 -> 2048.147 | K27: =((MAX(G27:G49)-MIN(G27:G49))/SUM(H28:H49)) * 60 -> 0.86424537 | L27: =((FLOOR(MAX(G27:G49), 1)-FLOOR(MIN(G27:G49), 1))/SUM(H28:H49)) * 60 -> 0.8611743 | M27: 0 | N27: =(MID(F27, 2, 7) + MID(F27, 12, 8)) / 2 -> 0.852991
D28: 2024-09-12 17:20:30.688491 | E28: 2024-09-12 17:54:39.992448 | F28: [0.688491, 0.703596] | G28: =(DATEVALUE(LEFT(E28, 10))-DATEVALUE(LEFT(D28, 10))) * 86400 + (TIMEVALUE(MID(E28, 12, 8)) - TIMEVALUE(MID(D28, 12, 8))) * 86400 + (VALUE(RIGHT(E28, 6)) - VALUE(RIGHT(D28, 6))) / 1000000 -> 2049.304 | H28: =((DATEVALUE(LEFT(D28,10))-DATEVALUE(LEFT(D27,10)))*86400+(TIMEVALUE(MID(D28,12,8))-TIMEVALUE(MID(D27,12,8)))*86400+(VALUE(RIGHT(D28,6))-VALUE(RIGHT(D27,6)))/1000000)/ 60 -> 77.997398 | I28: =3600 * (G28-G27) / ((DATEVALUE(LEFT(D28, 10))-DATEVALUE(LEFT(D27, 10))) * 86400 + (TIMEVALUE(MID(D28, 12, 8)) - TIMEVALUE(MID(D27, 12, 8))) * 86400 + (VALUE(RIGHT(D28, 6)) - VALUE(RIGHT(D27, 6))) / 1000000) -> 0.88999122 | J28: =(FLOOR(G28, 1) - FLOOR(G27, 1)) / H28 * 60 -> 0.76925643 | M28: =M27 + H28 -> 77.997398 | N28: =(MID(F28, 2, 7) + MID(F28, 12, 8)) / 2 -> 0.696043
D29: 2024-09-12 18:37:28.563499 | E29: 2024-09-12 19:11:38.992364 | F29: [0.563499, 0.578772] | G29: =(DATEVALUE(LEFT(E29, 10))-DATEVALUE(LEFT(D29, 10))) * 86400 + (TIMEVALUE(MID(E29, 12, 8)) - TIMEVALUE(MID(D29, 12, 8))) * 86400 + (VALUE(RIGHT(E29, 6)) - VALUE(RIGHT(D29, 6))) / 1000000 -> 2050.4289 | H29: =((DATEVALUE(LEFT(D29,10))-DATEVALUE(LEFT(D28,10)))*86400+(TIMEVALUE(MID(D29,12,8))-TIMEVALUE(MID(D28,12,8)))*86400+(VALUE(RIGHT(D29,6))-VALUE(RIGHT(D28,6)))/1000000)/ 60 -> 76.964583 | I29: =3600 * (G29-G28) / ((DATEVALUE(LEFT(D29, 10))-DATEVALUE(LEFT(D28, 10))) * 86400 + (TIMEVALUE(MID(D29, 12, 8)) - TIMEVALUE(MID(D28, 12, 8))) * 86400 + (VALUE(RIGHT(D29, 6)) - VALUE(RIGHT(D28, 6))) / 1000000) -> 0.87695505 | J29: =(FLOOR(G29, 1) - FLOOR(G28, 1)) / H29 * 60 -> 0.77957935 | K29: Average with time set | L29: Average error before measure | M29: =M28 + H29 -> 154.96198 | N29: =(MID(F29, 2, 7) + MID(F29, 12, 8)) / 2 -> 0.571131
D30: 2024-09-12 19:38:46.657944 | E30: 2024-09-12 20:12:57.992703 | F30: [0.657944, 0.672538] | G30: =(DATEVALUE(LEFT(E30, 10))-DATEVALUE(LEFT(D30, 10))) * 86400 + (TIMEVALUE(MID(E30, 12, 8)) - TIMEVALUE(MID(D30, 12, 8))) * 86400 + (VALUE(RIGHT(E30, 6)) - VALUE(RIGHT(D30, 6))) / 1000000 -> 2051.3348 | H30: =((DATEVALUE(LEFT(D30,10))-DATEVALUE(LEFT(D29,10)))*86400+(TIMEVALUE(MID(D30,12,8))-TIMEVALUE(MID(D29,12,8)))*86400+(VALUE(RIGHT(D30,6))-VALUE(RIGHT(D29,6)))/1000000)/ 60 -> 61.301574 | I30: =3600 * (G30-G29) / ((DATEVALUE(LEFT(D30, 10))-DATEVALUE(LEFT(D29, 10))) * 86400 + (TIMEVALUE(MID(D30, 12, 8)) - TIMEVALUE(MID(D29, 12, 8))) * 86400 + (VALUE(RIGHT(D30, 6)) - VALUE(RIGHT(D29, 6))) / 1000000) -> 0.88665978 | J30: =(FLOOR(G30, 1) - FLOOR(G29, 1)) / H30 * 60 -> 0.97876769 | K30: =(MAX(G27:G49) / (DATEDIF(VALUE(DATE(2000 + MID(B13, 1, 2), MID(B13, 4, 2), MID(B13, 7, 2))), VALUE(DATEVALUE(MID(D27, 1, 10)) + TIMEVALUE(MID(D27, 12, 8)) + MID(D27, 21, 6) / 86400000), "d") * 1440 + (TIMEVALUE(MID(D27, 12, 8)) - TIMEVALUE(RIGHT(B13, 8))) * 1440 + MID(D27, 21, 6) / 86400000 + MAX(M27:M49))) * 60 -> 0.9968373 | L30: =(MIN(G27:G49) / (DATEDIF(VALUE(DATE(2000 + MID(B13, 1, 2), MID(B13, 4, 2), MID(B13, 7, 2))), VALUE(DATEVALUE(MID(D27, 1, 10)) + TIMEVALUE(MID(D27, 12, 8)) + MID(D27, 21, 6) / 86400000), "d") * 1440 + (TIMEVALUE(MID(D27, 12, 8)) - TIMEVALUE(RIGHT(B13, 8))) * 1440 + MID(D27, 21, 6) / 86400000)) * 60 -> 1.0115128 | M30: =M29 + H30 -> 216.26356 | N30: =(MID(F30, 2, 7) + MID(F30, 12, 8)) / 2 -> 0.665239
D31: 2024-09-13 00:21:17.532209 | E31: 2024-09-13 00:55:32.992165 | F31: [0.532209, 0.547879] | G31: =(DATEVALUE(LEFT(E31, 10))-DATEVALUE(LEFT(D31, 10))) * 86400 + (TIMEVALUE(MID(E31, 12, 8)) - TIMEVALUE(MID(D31, 12, 8))) * 86400 + (VALUE(RIGHT(E31, 6)) - VALUE(RIGHT(D31, 6))) / 1000000 -> 2055.46 | H31: =((DATEVALUE(LEFT(D31,10))-DATEVALUE(LEFT(D30,10)))*86400+(TIMEVALUE(MID(D31,12,8))-TIMEVALUE(MID(D30,12,8)))*86400+(VALUE(RIGHT(D31,6))-VALUE(RIGHT(D30,6)))/1000000)/ 60 -> 282.51457 | I31: =3600 * (G31-G30) / ((DATEVALUE(LEFT(D31, 10))-DATEVALUE(LEFT(D30, 10))) * 86400 + (TIMEVALUE(MID(D31, 12, 8)) - TIMEVALUE(MID(D30, 12, 8))) * 86400 + (VALUE(RIGHT(D31, 6)) - VALUE(RIGHT(D30, 6))) / 1000000) -> 0.87610285 | J31: =(FLOOR(G31, 1) - FLOOR(G30, 1)) / H31 * 60 -> 0.84951371 | M31: =M30 + H31 -> 498.77813 | N31: =(MID(F31, 2, 7) + MID(F31, 12, 8)) / 2 -> 0.5400395
D32: 2024-09-13 10:38:52.750590 | E32: 2024-09-13 11:13:14.992419 | F32: [0.750590, 0.765752] | G32: =(DATEVALUE(LEFT(E32, 10))-DATEVALUE(LEFT(D32, 10))) * 86400 + (TIMEVALUE(MID(E32, 12, 8)) - TIMEVALUE(MID(D32, 12, 8))) * 86400 + (VALUE(RIGHT(E32, 6)) - VALUE(RIGHT(D32, 6))) / 1000000 -> 2062.2418 | H32: =((DATEVALUE(LEFT(D32,10))-DATEVALUE(LEFT(D31,10)))*86400+(TIMEVALUE(MID(D32,12,8))-TIMEVALUE(MID(D31,12,8)))*86400+(VALUE(RIGHT(D32,6))-VALUE(RIGHT(D31,6)))/1000000)/ 60 -> 617.58697 | I32: =3600 * (G32-G31) / ((DATEVALUE(LEFT(D32, 10))-DATEVALUE(LEFT(D31, 10))) * 86400 + (TIMEVALUE(MID(D32, 12, 8)) - TIMEVALUE(MID(D31, 12, 8))) * 86400 + (VALUE(RIGHT(D32, 6)) - VALUE(RIGHT(D31, 6))) / 1000000) -> 0.65887462 | J32: =(FLOOR(G32, 1) - FLOOR(G31, 1)) / H32 * 60 -> 0.68006616 | K32: Standard Deviation | M32: =M31 + H32 -> 1116.3651 | N32: =(MID(F32, 2, 7) + MID(F32, 12, 8)) / 2 -> 0.758171
D33: 2024-09-13 12:22:57.219903 | E33: 2024-09-13 12:57:20.992420 | F33: [0.219903, 0.235062] | G33: =(DATEVALUE(LEFT(E33, 10))-DATEVALUE(LEFT(D33, 10))) * 86400 + (TIMEVALUE(MID(E33, 12, 8)) - TIMEVALUE(MID(D33, 12, 8))) * 86400 + (VALUE(RIGHT(E33, 6)) - VALUE(RIGHT(D33, 6))) / 1000000 -> 2063.7725 | H33: =((DATEVALUE(LEFT(D33,10))-DATEVALUE(LEFT(D32,10)))*86400+(TIMEVALUE(MID(D33,12,8))-TIMEVALUE(MID(D32,12,8)))*86400+(VALUE(RIGHT(D33,6))-VALUE(RIGHT(D32,6)))/1000000)/ 60 -> 104.07449 | I33: =3600 * (G33-G32) / ((DATEVALUE(LEFT(D33, 10))-DATEVALUE(LEFT(D32, 10))) * 86400 + (TIMEVALUE(MID(D33, 12, 8)) - TIMEVALUE(MID(D32, 12, 8))) * 86400 + (VALUE(RIGHT(D33, 6)) - VALUE(RIGHT(D32, 6))) / 1000000) -> 0.88245718 | J33: =(FLOOR(G33, 1) - FLOOR(G32, 1)) / H33 * 60 -> 0.57651016 | K33: =_xlfn.STDEV.P(I28:I48) -> 0.052133425 | M33: =M32 + H33 -> 1220.4396 | N33: =(MID(F33, 2, 7) + MID(F33, 12, 8)) / 2 -> 0.227481
D34: 2024-09-13 13:24:52.313229 | E34: 2024-09-13 13:59:16.992248 | F34: [0.313229, 0.328733] | G34: =(DATEVALUE(LEFT(E34, 10))-DATEVALUE(LEFT(D34, 10))) * 86400 + (TIMEVALUE(MID(E34, 12, 8)) - TIMEVALUE(MID(D34, 12, 8))) * 86400 + (VALUE(RIGHT(E34, 6)) - VALUE(RIGHT(D34, 6))) / 1000000 -> 2064.679 | H34: =((DATEVALUE(LEFT(D34,10))-DATEVALUE(LEFT(D33,10)))*86400+(TIMEVALUE(MID(D34,12,8))-TIMEVALUE(MID(D33,12,8)))*86400+(VALUE(RIGHT(D34,6))-VALUE(RIGHT(D33,6)))/1000000)/ 60 -> 61.918222 | I34: =3600 * (G34-G33) / ((DATEVALUE(LEFT(D34, 10))-DATEVALUE(LEFT(D33, 10))) * 86400 + (TIMEVALUE(MID(D34, 12, 8)) - TIMEVALUE(MID(D33, 12, 8))) * 86400 + (VALUE(RIGHT(D34, 6)) - VALUE(RIGHT(D33, 6))) / 1000000) -> 0.87841863 | J34: =(FLOOR(G34, 1) - FLOOR(G33, 1)) / H34 * 60 -> 0.96902007 | M34: =M33 + H34 -> 1282.3578 | N34: =(MID(F34, 2, 7) + MID(F34, 12, 8)) / 2 -> 0.3209765
D35: 2024-09-13 17:00:16.157644 | E35: 2024-09-13 17:34:43.992635 | F35: [0.157644, 0.172374] | G35: =(DATEVALUE(LEFT(E35, 10))-DATEVALUE(LEFT(D35, 10))) * 86400 + (TIMEVALUE(MID(E35, 12, 8)) - TIMEVALUE(MID(D35, 12, 8))) * 86400 + (VALUE(RIGHT(E35, 6)) - VALUE(RIGHT(D35, 6))) / 1000000 -> 2067.835 | H35: =((DATEVALUE(LEFT(D35,10))-DATEVALUE(LEFT(D34,10)))*86400+(TIMEVALUE(MID(D35,12,8))-TIMEVALUE(MID(D34,12,8)))*86400+(VALUE(RIGHT(D35,6))-VALUE(RIGHT(D34,6)))/1000000)/ 60 -> 215.39741 | I35: =3600 * (G35-G34) / ((DATEVALUE(LEFT(D35, 10))-DATEVALUE(LEFT(D34, 10))) * 86400 + (TIMEVALUE(MID(D35, 12, 8)) - TIMEVALUE(MID(D34, 12, 8))) * 86400 + (VALUE(RIGHT(D35, 6)) - VALUE(RIGHT(D34, 6))) / 1000000) -> 0.87911142 | J35: =(FLOOR(G35, 1) - FLOOR(G34, 1)) / H35 * 60 -> 0.83566466 | M35: =M34 + H35 -> 1497.7552 | N35: =(MID(F35, 2, 7) + MID(F35, 12, 8)) / 2 -> 0.165007
D36: 2024-09-14 13:04:31.532492 | E36: 2024-09-14 13:39:16.992400 | F36: [0.532492, 0.547691] | G36: =(DATEVALUE(LEFT(E36, 10))-DATEVALUE(LEFT(D36, 10))) * 86400 + (TIMEVALUE(MID(E36, 12, 8)) - TIMEVALUE(MID(D36, 12, 8))) * 86400 + (VALUE(RIGHT(E36, 6)) - VALUE(RIGHT(D36, 6))) / 1000000 -> 2085.4599 | H36: =((DATEVALUE(LEFT(D36,10))-DATEVALUE(LEFT(D35,10)))*86400+(TIMEVALUE(MID(D36,12,8))-TIMEVALUE(MID(D35,12,8)))*86400+(VALUE(RIGHT(D36,6))-VALUE(RIGHT(D35,6)))/1000000)/ 60 -> 1204.2562 | I36: =3600 * (G36-G35) / ((DATEVALUE(LEFT(D36, 10))-DATEVALUE(LEFT(D35, 10))) * 86400 + (TIMEVALUE(MID(D36, 12, 8)) - TIMEVALUE(MID(D35, 12, 8))) * 86400 + (VALUE(RIGHT(D36, 6)) - VALUE(RIGHT(D35, 6))) / 1000000) -> 0.87813123 | J36: =(FLOOR(G36, 1) - FLOOR(G35, 1)) / H36 * 60 -> 0.8968191 | M36: =M35 + H36 -> 2702.0115 | N36: =(MID(F36, 2, 7) + MID(F36, 12, 8)) / 2 -> 0.5400905
D37: 2024-09-14 15:08:32.688717 | E37: 2024-09-14 15:43:19.992576 | F37: [0.703861, 0.719105] | G37: =(DATEVALUE(LEFT(E37, 10))-DATEVALUE(LEFT(D37, 10))) * 86400 + (TIMEVALUE(MID(E37, 12, 8)) - TIMEVALUE(MID(D37, 12, 8))) * 86400 + (VALUE(RIGHT(E37, 6)) - VALUE(RIGHT(D37, 6))) / 1000000 -> 2087.3039 | H37: =((DATEVALUE(LEFT(D37,10))-DATEVALUE(LEFT(D36,10)))*86400+(TIMEVALUE(MID(D37,12,8))-TIMEVALUE(MID(D36,12,8)))*86400+(VALUE(RIGHT(D37,6))-VALUE(RIGHT(D36,6)))/1000000)/ 60 -> 124.01927 | I37: =3600 * (G37-G36) / ((DATEVALUE(LEFT(D37, 10))-DATEVALUE(LEFT(D36, 10))) * 86400 + (TIMEVALUE(MID(D37, 12, 8)) - TIMEVALUE(MID(D36, 12, 8))) * 86400 + (VALUE(RIGHT(D37, 6)) - VALUE(RIGHT(D36, 6))) / 1000000) -> 0.89209572 | J37: =(FLOOR(G37, 1) - FLOOR(G36, 1)) / H37 * 60 -> 0.96759157 | M37: =M36 + H37 -> 2826.0307 | N37: =(MID(F37, 2, 7) + MID(F37, 12, 8)) / 2 -> 0.7114825
D38: 2024-09-15 01:26:35.594115 | E38: 2024-09-15 02:01:31.992216 | F38: [0.609950, 0.625116] | G38: =(DATEVALUE(LEFT(E38, 10))-DATEVALUE(LEFT(D38, 10))) * 86400 + (TIMEVALUE(MID(E38, 12, 8)) - TIMEVALUE(MID(D38, 12, 8))) * 86400 + (VALUE(RIGHT(E38, 6)) - VALUE(RIGHT(D38, 6))) / 1000000 -> 2096.3981 | H38: =((DATEVALUE(LEFT(D38,10))-DATEVALUE(LEFT(D37,10)))*86400+(TIMEVALUE(MID(D38,12,8))-TIMEVALUE(MID(D37,12,8)))*86400+(VALUE(RIGHT(D38,6))-VALUE(RIGHT(D37,6)))/1000000)/ 60 -> 618.04842 | I38: =3600 * (G38-G37) / ((DATEVALUE(LEFT(D38, 10))-DATEVALUE(LEFT(D37, 10))) * 86400 + (TIMEVALUE(MID(D38, 12, 8)) - TIMEVALUE(MID(D37, 12, 8))) * 86400 + (VALUE(RIGHT(D38, 6)) - VALUE(RIGHT(D37, 6))) / 1000000) -> 0.88286694 | J38: =(FLOOR(G38, 1) - FLOOR(G37, 1)) / H38 * 60 -> 0.87371795 | M38: =M37 + H38 -> 3444.0792 | N38: =(MID(F38, 2, 7) + MID(F38, 12, 8)) / 2 -> 0.617533
D39: 2024-09-15 12:12:19.156723 | E39: 2024-09-15 12:47:24.992338 | F39: [0.172439, 0.188944] | G39: =(DATEVALUE(LEFT(E39, 10))-DATEVALUE(LEFT(D39, 10))) * 86400 + (TIMEVALUE(MID(E39, 12, 8)) - TIMEVALUE(MID(D39, 12, 8))) * 86400 + (VALUE(RIGHT(E39, 6)) - VALUE(RIGHT(D39, 6))) / 1000000 -> 2105.8356 | H39: =((DATEVALUE(LEFT(D39,10))-DATEVALUE(LEFT(D38,10)))*86400+(TIMEVALUE(MID(D39,12,8))-TIMEVALUE(MID(D38,12,8)))*86400+(VALUE(RIGHT(D39,6))-VALUE(RIGHT(D38,6)))/1000000)/ 60 -> 645.72604 | I39: =3600 * (G39-G38) / ((DATEVALUE(LEFT(D39, 10))-DATEVALUE(LEFT(D38, 10))) * 86400 + (TIMEVALUE(MID(D39, 12, 8)) - TIMEVALUE(MID(D38, 12, 8))) * 86400 + (VALUE(RIGHT(D39, 6)) - VALUE(RIGHT(D38, 6))) / 1000000) -> 0.87692117 | J39: =(FLOOR(G39, 1) - FLOOR(G38, 1)) / H39 * 60 -> 0.83626796 | M39: =M38 + H39 -> 4089.8052 | N39: =(MID(F39, 2, 7) + MID(F39, 12, 8)) / 2 -> 0.180687
D40: 2024-09-15 22:24:06.159025 | E40: 2024-09-15 22:59:20.993478 | F40: [0.159025, 0.172070] | G40: =(DATEVALUE(LEFT(E40, 10))-DATEVALUE(LEFT(D40, 10))) * 86400 + (TIMEVALUE(MID(E40, 12, 8)) - TIMEVALUE(MID(D40, 12, 8))) * 86400 + (VALUE(RIGHT(E40, 6)) - VALUE(RIGHT(D40, 6))) / 1000000 -> 2114.8345 | H40: =((DATEVALUE(LEFT(D40,10))-DATEVALUE(LEFT(D39,10)))*86400+(TIMEVALUE(MID(D40,12,8))-TIMEVALUE(MID(D39,12,8)))*86400+(VALUE(RIGHT(D40,6))-VALUE(RIGHT(D39,6)))/1000000)/ 60 -> 611.78337 | I40: =3600 * (G40-G39) / ((DATEVALUE(LEFT(D40, 10))-DATEVALUE(LEFT(D39, 10))) * 86400 + (TIMEVALUE(MID(D40, 12, 8)) - TIMEVALUE(MID(D39, 12, 8))) * 86400 + (VALUE(RIGHT(D40, 6)) - VALUE(RIGHT(D39, 6))) / 1000000) -> 0.88255141 | J40: =(FLOOR(G40, 1) - FLOOR(G39, 1)) / H40 * 60 -> 0.88266538 | M40: =M39 + H40 -> 4701.5886 | N40: =(MID(F40, 2, 7) + MID(F40, 12, 8)) / 2 -> 0.165545
D41: 2024-09-16 11:18:57.813008 | E41: 2024-09-16 11:54:23.991996 | F41: [0.813008, 0.829016] | G41: =(DATEVALUE(LEFT(E41, 10))-DATEVALUE(LEFT(D41, 10))) * 86400 + (TIMEVALUE(MID(E41, 12, 8)) - TIMEVALUE(MID(D41, 12, 8))) * 86400 + (VALUE(RIGHT(E41, 6)) - VALUE(RIGHT(D41, 6))) / 1000000 -> 2126.179 | H41: =((DATEVALUE(LEFT(D41,10))-DATEVALUE(LEFT(D40,10)))*86400+(TIMEVALUE(MID(D41,12,8))-TIMEVALUE(MID(D40,12,8)))*86400+(VALUE(RIGHT(D41,6))-VALUE(RIGHT(D40,6)))/1000000)/ 60 -> 774.8609 | I41: =3600 * (G41-G40) / ((DATEVALUE(LEFT(D41, 10))-DATEVALUE(LEFT(D40, 10))) * 86400 + (TIMEVALUE(MID(D41, 12, 8)) - TIMEVALUE(MID(D40, 12, 8))) * 86400 + (VALUE(RIGHT(D41, 6)) - VALUE(RIGHT(D40, 6))) / 1000000) -> 0.87844425 | J41: =(FLOOR(G41, 1) - FLOOR(G40, 1)) / H41 * 60 -> 0.92919903 | M41: =M40 + H41 -> 5476.4495 | N41: =(MID(F41, 2, 7) + MID(F41, 12, 8)) / 2 -> 0.821008
...

Sheet Calibrated
A1: Device Label | B1: Device № | D1: =("№"&B3&" - "&A3) -> №2 - Blue tape
A2: Nothing | B2: 1 | D2: Actual time | E2: Device time | F2: Interval | G2: Time drift (s) | H2: Time elapsed minutes | I2: Time drift per hour (with ms) | J2: Time drift per hour | K2: Average error (with ms) | L2: Average error (s/hr) | M2: Time from start (minutes) | N2: Interval | X2: Device name | Y2: Time drift (s/hr) | Z2: Correction Value | AA2: Predicted drift | AB2: New Time Drift | AC2: Time drift reduced by % | AD2: Actual correction value: | AE2: Average correction value:
A3: Blue tape | B3: 2 | D3: 2024-09-22 01:44:38.159164 | E3: 2024-09-22 01:44:37.988356 | F3: [0.172761, 0.187991] | G3: =(DATEVALUE(LEFT(E3, 10))-DATEVALUE(LEFT(D3, 10))) * 86400 + (TIMEVALUE(MID(E3, 12, 8)) - TIMEVALUE(MID(D3, 12, 8))) * 86400 + (VALUE(RIGHT(E3, 6)) - VALUE(RIGHT(D3, 6))) / 1000000 -> -0.170808 | K3: {=((LOOKUP(2,1/(G3:G24<>""),G3:G24) - G3)/SUM(H4:H25)) * 60} -> -0.065507438 | L3: =((FLOOR(MAX(G3:G25), 1)-FLOOR(MIN(G3:G25), 1))/SUM(H4:H25)) * 60 -> 0.062929805 | M3: 0 | N3: =(MID(F3, 2, 7) + MID(F3, 12, 8)) / 2 -> 0.1803755 | X3: №1 - Nothing | Y3: =Uncalibrated!K171 -> 0.83394774 | Z3: =267 * 0.9537 * 3600 / 1000000 -> 0.91669644 | AA3: =Y3-Z3 -> -0.082748702 | AB3: =K171 -> -0.070984921 | AC3: =(1 - ABS(AB3)/ABS(Y3)) * 100 -> 91.488085 | AD3: =Y3 - AB3 -> 0.90493266 | AE3: =AVERAGE(AD3:AD10) -> 0.90959714
A4: ACCZERO PBRC | B4: 3 | D4: 2024-09-22 01:59:50.188188 | E4: 2024-09-22 01:59:49.992056 | F4: [0.188188, 0.204077] | G4: =(DATEVALUE(LEFT(E4, 10))-DATEVALUE(LEFT(D4, 10))) * 86400 + (TIMEVALUE(MID(E4, 12, 8)) - TIMEVALUE(MID(D4, 12, 8))) * 86400 + (VALUE(RIGHT(E4, 6)) - VALUE(RIGHT(D4, 6))) / 1000000 -> -0.196132 | H4: =((DATEVALUE(LEFT(D4,10))-DATEVALUE(LEFT(D3,10)))*86400+(TIMEVALUE(MID(D4,12,8))-TIMEVALUE(MID(D3,12,8)))*86400+(VALUE(RIGHT(D4,6))-VALUE(RIGHT(D3,6)))/1000000)/ 60 -> 15.200484 | I4: =(G4 - G3) / H4 * 60 -> -0.099959977 | J4: =(FLOOR(G4, 1) - FLOOR(G3, 1)) / H4 * 60 -> 0 | M4: =M3 + H4 -> 15.200484 | N4: =(MID(F4, 2, 7) + MID(F4, 12, 8)) / 2 -> 0.1961285 | X4: №2 - Blue tape | Y4: =Uncalibrated!K3 -> 0.84065639 | Z4: =267 * 0.9537 * 3600 / 1000000 -> 0.91669644 | AA4: =Y4-Z4 -> -0.076040051 | AB4: =K3 -> -0.065507438 | AC4: =(1 - ABS(AB4)/ABS(Y4)) * 100 -> 92.207585 | AD4: =Y4 - AB4 -> 0.90616383
A5: IMGCOF | B5: 4 | D5: 2024-09-22 11:42:44.814252 | E5: 2024-09-22 11:42:43.992848 | F5: [0.814252, 0.828557] | G5: =(DATEVALUE(LEFT(E5, 10))-DATEVALUE(LEFT(D5, 10))) * 86400 + (TIMEVALUE(MID(E5, 12, 8)) - TIMEVALUE(MID(D5, 12, 8))) * 86400 + (VALUE(RIGHT(E5, 6)) - VALUE(RIGHT(D5, 6))) / 1000000 -> -0.821404 | H5: =((DATEVALUE(LEFT(D5,10))-DATEVALUE(LEFT(D4,10)))*86400+(TIMEVALUE(MID(D5,12,8))-TIMEVALUE(MID(D4,12,8)))*86400+(VALUE(RIGHT(D5,6))-VALUE(RIGHT(D4,6)))/1000000)/ 60 -> 582.91043 | I5: =(G5 - G4) / H5 * 60 -> -0.064360351 | J5: =(FLOOR(G5, 1) - FLOOR(G4, 1)) / H5 * 60 -> 0 | K5: Average with time set | M5: =M4 + H5 -> 598.11092 | N5: =(MID(F5, 2, 7) + MID(F5, 12, 8)) / 2 -> 0.8214035 | X5: №3 - ACCZERO PBRC | Y5: =Uncalibrated!K27 -> 0.86424537 | Z5: =267 * 0.9537 * 3600 / 1000000 -> 0.91669644 | AA5: =Y5-Z5 -> -0.052451068 | AB5: =K27 -> -0.047342906 | AC5: =(1 - ABS(AB5)/ABS(Y5)) * 100 -> 94.522053 | AD5: =Y5 - AB5 -> 0.91158828 | AE5: Correction value error:
A6: ERR15 | B6: 5 | D6: 2024-09-22 18:16:10.157452 | E6: 2024-09-22 18:16:08.992724 | F6: [0.172188, 0.188029] | G6: =(DATEVALUE(LEFT(E6, 10))-DATEVALUE(LEFT(D6, 10))) * 86400 + (TIMEVALUE(MID(E6, 12, 8)) - TIMEVALUE(MID(D6, 12, 8))) * 86400 + (VALUE(RIGHT(E6, 6)) - VALUE(RIGHT(D6, 6))) / 1000000 -> -1.164728 | H6: =((DATEVALUE(LEFT(D6,10))-DATEVALUE(LEFT(D5,10)))*86400+(TIMEVALUE(MID(D6,12,8))-TIMEVALUE(MID(D5,12,8)))*86400+(VALUE(RIGHT(D6,6))-VALUE(RIGHT(D5,6)))/1000000)/ 60 -> 393.42239 | I6: =(G6 - G5) / H6 * 60 -> -0.052359603 | J6: =(FLOOR(G6, 1) - FLOOR(G5, 1)) / H6 * 60 -> -0.15250784 | K6: =(MAX(G3:G24)/(DATEDIF(VALUE(DATE(2000 + MID(B12, 1, 2), MID(B12, 4, 2), MID(B12, 7, 2))),VALUE(MID(D3, 1, 10)),"d")*(60*24)+(TIMEVALUE(MID(D3,12,8))-TIMEVALUE(RIGHT(B12,8))*24*60+MID(D3,21,6)/86400000+MAX(M3:M25)))) * 60 -> -0.0012087851 | M6: =M5 + H6 -> 991.5333 | N6: =(MID(F6, 2, 7) + MID(F6, 12, 8)) / 2 -> 0.1801045 | X6: №4 - IMGCOF | Y6: =Uncalibrated!K51 -> 0.86373195 | Z6: =267 * 0.9537 * 3600 / 1000000 -> 0.91669644 | AA6: =Y6-Z6 -> -0.05296449 | AB6: =K51 -> -0.046450805 | AC6: =(1 - ABS(AB6)/ABS(Y6)) * 100 -> 94.622081 | AD6: =Y6 - AB6 -> 0.91018275 | AE6: =(Z3 / AE3) * 100 -> 100.78049
A7: IMG COR LSU | B7: 6 | D7: 2024-09-23 10:11:08.531382 | E7: 2024-09-23 10:11:06.992079 | F7: [0.531382, 0.547224] | G7: =(DATEVALUE(LEFT(E7, 10))-DATEVALUE(LEFT(D7, 10))) * 86400 + (TIMEVALUE(MID(E7, 12, 8)) - TIMEVALUE(MID(D7, 12, 8))) * 86400 + (VALUE(RIGHT(E7, 6)) - VALUE(RIGHT(D7, 6))) / 1000000 -> -1.539303 | H7: =((DATEVALUE(LEFT(D7,10))-DATEVALUE(LEFT(D6,10)))*86400+(TIMEVALUE(MID(D7,12,8))-TIMEVALUE(MID(D6,12,8)))*86400+(VALUE(RIGHT(D7,6))-VALUE(RIGHT(D6,6)))/1000000)/ 60 -> 954.9729 | I7: =(G7 - G6) / H7 * 60 -> -0.023534176 | J7: =(FLOOR(G7, 1) - FLOOR(G6, 1)) / H7 * 60 -> 0 | M7: =M6 + H7 -> 1946.5062 | N7: =(MID(F7, 2, 7) + MID(F7, 12, 8)) / 2 -> 0.539302 | X7: №5 - ERR15 | Y7: =Uncalibrated!K75 -> 0.90240489 | Z7: =267 * 0.9537 * 3600 / 1000000 -> 0.91669644 | AA7: =Y7-Z7 -> -0.014291547 | AB7: =K75 -> -0.0082762451 | AC7: =(1 - ABS(AB7)/ABS(Y7)) * 100 -> 99.082868 | AD7: =Y7 - AB7 -> 0.91068114
A8: IVAN ERR15 | B8: 7 | D8: 2024-09-23 13:41:50.720575 | E8: 2024-09-23 13:41:48.992855 | F8: [0.734707, 0.750841] | G8: =(DATEVALUE(LEFT(E8, 10))-DATEVALUE(LEFT(D8, 10))) * 86400 + (TIMEVALUE(MID(E8, 12, 8)) - TIMEVALUE(MID(D8, 12, 8))) * 86400 + (VALUE(RIGHT(E8, 6)) - VALUE(RIGHT(D8, 6))) / 1000000 -> -1.72772 | H8: =((DATEVALUE(LEFT(D8,10))-DATEVALUE(LEFT(D7,10)))*86400+(TIMEVALUE(MID(D8,12,8))-TIMEVALUE(MID(D7,12,8)))*86400+(VALUE(RIGHT(D8,6))-VALUE(RIGHT(D7,6)))/1000000)/ 60 -> 210.70315 | I8: =(G8 - G7) / H8 * 60 -> -0.053653777 | J8: =(FLOOR(G8, 1) - FLOOR(G7, 1)) / H8 * 60 -> 0 | K8: Standard Deviation | M8: =M7 + H8 -> 2157.2094 | N8: =(MID(F8, 2, 7) + MID(F8, 12, 8)) / 2 -> 0.7427705 | X8: №6 - IMG COR LSU | Y8: =Uncalibrated!K99 -> 0.98479347 | Z8: =267 * 0.9537 * 3600 / 1000000 -> 0.91669644 | AA8: =Y8-Z8 -> 0.068097029 | AB8: =K99 -> 0.072696316 | AC8: =(1 - ABS(AB8)/ABS(Y8)) * 100 -> 92.618116 | AD8: =Y8 - AB8 -> 0.91209715
A9: AIM TRAINING DEVICE | B9: 8 | D9: 2024-09-23 23:51:44.563335 | E9: 2024-09-23 23:51:40.992362 | F9: [0.563335, 0.578611] | G9: =(DATEVALUE(LEFT(E9, 10))-DATEVALUE(LEFT(D9, 10))) * 86400 + (TIMEVALUE(MID(E9, 12, 8)) - TIMEVALUE(MID(D9, 12, 8))) * 86400 + (VALUE(RIGHT(E9, 6)) - VALUE(RIGHT(D9, 6))) / 1000000 -> -3.570973 | H9: =((DATEVALUE(LEFT(D9,10))-DATEVALUE(LEFT(D8,10)))*86400+(TIMEVALUE(MID(D9,12,8))-TIMEVALUE(MID(D8,12,8)))*86400+(VALUE(RIGHT(D9,6))-VALUE(RIGHT(D8,6)))/1000000)/ 60 -> 609.89738 | I9: =(G9 - G8) / H9 * 60 -> -0.18133408 | J9: =(FLOOR(G9, 1) - FLOOR(G8, 1)) / H9 * 60 -> -0.19675441 | K9: =_xlfn.STDEV.P(I4:I24) -> 0.034684281 | M9: =M8 + H9 -> 2767.1067 | N9: =(MID(F9, 2, 7) + MID(F9, 12, 8)) / 2 -> 0.5709705 | X9: №7 - IVAN ERR15 | Y9: =Uncalibrated!K123 -> 1.0233367 | Z9: =267 * 0.9537 * 3600 / 1000000 -> 0.91669644 | AA9: =Y9-Z9 -> 0.10664021 | AB9: =K123 -> 0.11344305 | AC9: =(1 - ABS(AB9)/ABS(Y9)) * 100 -> 88.914396 | AD9: =Y9 - AB9 -> 0.9098936
A10: Device name | B10: Last time set time | D10: 2024-09-24 10:25:32.314315 | E10: 2024-09-24 10:25:27.992900 | F10: [0.314315, 0.328516] | G10: =(DATEVALUE(LEFT(E10, 10))-DATEVALUE(LEFT(D10, 10))) * 86400 + (TIMEVALUE(MID(E10, 12, 8)) - TIMEVALUE(MID(D10, 12, 8))) * 86400 + (VALUE(RIGHT(E10, 6)) - VALUE(RIGHT(D10, 6))) / 1000000 -> -4.321415 | H10: =((DATEVALUE(LEFT(D10,10))-DATEVALUE(LEFT(D9,10)))*86400+(TIMEVALUE(MID(D10,12,8))-TIMEVALUE(MID(D9,12,8)))*86400+(VALUE(RIGHT(D10,6))-VALUE(RIGHT(D9,6)))/1000000)/ 60 -> 633.79585 | I10: =(G10 - G9) / H10 * 60 -> -0.071042624 | J10: =(FLOOR(G10, 1) - FLOOR(G9, 1)) / H10 * 60 -> -0.094667707 | M10: =M9 + H10 -> 3400.9026 | N10: =(MID(F10, 2, 7) + MID(F10, 12, 8)) / 2 -> 0.321413 | X10: №8 - AIM TRAINING DEVICE | Y10: =Uncalibrated!K147 -> 0.93265426 | Z10: =267 * 0.9537 * 3600 / 1000000 -> 0.91669644 | AA10: =Y10-Z10 -> 0.015957823 | AB10: =K147 -> 0.021416528 | AC10: =(1 - ABS(AB10)/ABS(Y10)) * 100 -> 97.703701 | AD10: =Y10 - AB10 -> 0.91123774
A11: =("№"&B2&" - "&A2) -> №1 - Nothing | B11: 24-09-22 18:55:58 | D11: 2024-09-25 00:57:32.095163 | E11: 2024-09-25 00:57:26.992588 | F11: [0.110213, 0.125531] | G11: =(DATEVALUE(LEFT(E11, 10))-DATEVALUE(LEFT(D11, 10))) * 86400 + (TIMEVALUE(MID(E11, 12, 8)) - TIMEVALUE(MID(D11, 12, 8))) * 86400 + (VALUE(RIGHT(E11, 6)) - VALUE(RIGHT(D11, 6))) / 1000000 -> -5.102575 | H11: =((DATEVALUE(LEFT(D11,10))-DATEVALUE(LEFT(D10,10)))*86400+(TIMEVALUE(MID(D11,12,8))-TIMEVALUE(MID(D10,12,8)))*86400+(VALUE(RIGHT(D11,6))-VALUE(RIGHT(D10,6)))/1000000)/ 60 -> 871.99635 | I11: =(G11 - G10) / H11 * 60 -> -0.053749766 | J11: =(FLOOR(G11, 1) - FLOOR(G10, 1)) / H11 * 60 -> -0.068807628 | M11: =M10 + H11 -> 4272.8989 | N11: =(MID(F11, 2, 7) + MID(F11, 12, 8)) / 2 -> 0.1178705
A12: =("№"&B3&" - "&A3) -> №2 - Blue tape | B12: 24-09-22 01:42:44 | D12: 2024-09-25 11:57:35.814015 | E12: 2024-09-25 11:57:29.992722 | F12: [0.814015, 0.828570] | G12: =(DATEVALUE(LEFT(E12, 10))-DATEVALUE(LEFT(D12, 10))) * 86400 + (TIMEVALUE(MID(E12, 12, 8)) - TIMEVALUE(MID(D12, 12, 8))) * 86400 + (VALUE(RIGHT(E12, 6)) - VALUE(RIGHT(D12, 6))) / 1000000 -> -5.821293 | H12: =((DATEVALUE(LEFT(D12,10))-DATEVALUE(LEFT(D11,10)))*86400+(TIMEVALUE(MID(D12,12,8))-TIMEVALUE(MID(D11,12,8)))*86400+(VALUE(RIGHT(D12,6))-VALUE(RIGHT(D11,6)))/1000000)/ 60 -> 660.06198 | I12: =(G12 - G11) / H12 * 60 -> -0.065331865 | J12: =(FLOOR(G12, 1) - FLOOR(G11, 1)) / H12 * 60 -> 0 | M12: =M11 + H12 -> 4932.9609 | N12: =(MID(F12, 2, 7) + MID(F12, 12, 8)) / 2 -> 0.82129
A13: =("№"&B4&" - "&A4) -> №3 - ACCZERO PBRC | B13: 24-09-22 01:10:55 | D13: 2024-09-25 23:34:40.501884 | E13: 2024-09-25 23:34:33.992905 | F13: [0.516766, 0.531535] | G13: =(DATEVALUE(LEFT(E13, 10))-DATEVALUE(LEFT(D13, 10))) * 86400 + (TIMEVALUE(MID(E13, 12, 8)) - TIMEVALUE(MID(D13, 12, 8))) * 86400 + (VALUE(RIGHT(E13, 6)) - VALUE(RIGHT(D13, 6))) / 1000000 -> -6.508979 | H13: =((DATEVALUE(LEFT(D13,10))-DATEVALUE(LEFT(D12,10)))*86400+(TIMEVALUE(MID(D13,12,8))-TIMEVALUE(MID(D12,12,8)))*86400+(VALUE(RIGHT(D13,6))-VALUE(RIGHT(D12,6)))/1000000)/ 60 -> 697.07813 | I13: =(G13 - G12) / H13 * 60 -> -0.059191586 | J13: =(FLOOR(G13, 1) - FLOOR(G12, 1)) / H13 * 60 -> -0.086073565 | M13: =M12 + H13 -> 5630.039 | N13: =(MID(F13, 2, 7) + MID(F13, 12, 8)) / 2 -> 0.5241475
A14: =("№"&B5&" - "&A5) -> №4 - IMGCOF | B14: 24-09-22 00:47:59 | D14: 2024-09-26 18:01:33.626289 | E14: 2024-09-26 18:01:25.992666 | F14: [0.641987, 0.656786] | G14: =(DATEVALUE(LEFT(E14, 10))-DATEVALUE(LEFT(D14, 10))) * 86400 + (TIMEVALUE(MID(E14, 12, 8)) - TIMEVALUE(MID(D14, 12, 8))) * 86400 + (VALUE(RIGHT(E14, 6)) - VALUE(RIGHT(D14, 6))) / 1000000 -> -7.633623 | H14: =((DATEVALUE(LEFT(D14,10))-DATEVALUE(LEFT(D13,10)))*86400+(TIMEVALUE(MID(D14,12,8))-TIMEVALUE(MID(D13,12,8)))*86400+(VALUE(RIGHT(D14,6))-VALUE(RIGHT(D13,6)))/1000000)/ 60 -> 1106.8854 | I14: =(G14 - G13) / H14 * 60 -> -0.060962625 | J14: =(FLOOR(G14, 1) - FLOOR(G13, 1)) / H14 * 60 -> -0.054206153 | M14: =M13 + H14 -> 6736.9245 | N14: =(MID(F14, 2, 7) + MID(F14, 12, 8)) / 2 -> 0.649383
A15: =("№"&B6&" - "&A6) -> №5 - ERR15 | B15: 24-09-22 01:16:05 | D15: 2024-09-27 02:01:09.063401 | E15: 2024-09-27 02:01:00.992229 | F15: [0.078695, 0.094485] | G15: =(DATEVALUE(LEFT(E15, 10))-DATEVALUE(LEFT(D15, 10))) * 86400 + (TIMEVALUE(MID(E15, 12, 8)) - TIMEVALUE(MID(D15, 12, 8))) * 86400 + (VALUE(RIGHT(E15, 6)) - VALUE(RIGHT(D15, 6))) / 1000000 -> -8.071172 | H15: =((DATEVALUE(LEFT(D15,10))-DATEVALUE(LEFT(D14,10)))*86400+(TIMEVALUE(MID(D15,12,8))-TIMEVALUE(MID(D14,12,8)))*86400+(VALUE(RIGHT(D15,6))-VALUE(RIGHT(D14,6)))/1000000)/ 60 -> 479.59062 | I15: =(G15 - G14) / H15 * 60 -> -0.054740312 | J15: =(FLOOR(G15, 1) - FLOOR(G14, 1)) / H15 * 60 -> -0.1251067 | M15: =M14 + H15 -> 7216.5151 | N15: =(MID(F15, 2, 7) + MID(F15, 12, 8)) / 2 -> 0.0865875
A16: =("№"&B7&" - "&A7) -> №6 - IMG COR LSU | B16: 24-09-22 01:21:08 | D16: 2024-09-27 12:31:34.719303 | E16: 2024-09-27 12:31:25.991974 | F16: [0.719303, 0.735356] | G16: =(DATEVALUE(LEFT(E16, 10))-DATEVALUE(LEFT(D16, 10))) * 86400 + (TIMEVALUE(MID(E16, 12, 8)) - TIMEVALUE(MID(D16, 12, 8))) * 86400 + (VALUE(RIGHT(E16, 6)) - VALUE(RIGHT(D16, 6))) / 1000000 -> -8.727329 | H16: =((DATEVALUE(LEFT(D16,10))-DATEVALUE(LEFT(D15,10)))*86400+(TIMEVALUE(MID(D16,12,8))-TIMEVALUE(MID(D15,12,8)))*86400+(VALUE(RIGHT(D16,6))-VALUE(RIGHT(D15,6)))/1000000)/ 60 -> 630.4276 | I16: =(G16 - G15) / H16 * 60 -> -0.062448757 | J16: =(FLOOR(G16, 1) - FLOOR(G15, 1)) / H16 * 60 -> 0 | M16: =M15 + H16 -> 7846.9427 | N16: =(MID(F16, 2, 7) + MID(F16, 12, 8)) / 2 -> 0.727328
A17: =("№"&B8&" - "&A8) -> №7 - IVAN ERR15 | B17: 24-09-22 01:26:36 | D17: 2024-09-28 00:45:37.531527 | E17: 2024-09-28 00:45:27.992075 | F17: [0.531527, 0.547377] | G17: =(DATEVALUE(LEFT(E17, 10))-DATEVALUE(LEFT(D17, 10))) * 86400 + (TIMEVALUE(MID(E17, 12, 8)) - TIMEVALUE(MID(D17, 12, 8))) * 86400 + (VALUE(RIGHT(E17, 6)) - VALUE(RIGHT(D17, 6))) / 1000000 -> -9.539452 | H17: =((DATEVALUE(LEFT(D17,10))-DATEVALUE(LEFT(D16,10)))*86400+(TIMEVALUE(MID(D17,12,8))-TIMEVALUE(MID(D16,12,8)))*86400+(VALUE(RIGHT(D17,6))-VALUE(RIGHT(D16,6)))/1000000)/ 60 -> 734.04687 | I17: =(G17 - G16) / H17 * 60 -> -0.066381837 | J17: =(FLOOR(G17, 1) - FLOOR(G16, 1)) / H17 * 60 -> -0.08173865 | M17: =M16 + H17 -> 8580.9895 | N17: =(MID(F17, 2, 7) + MID(F17, 12, 8)) / 2 -> 0.5394485
A18: =("№"&B9&" - "&A9) -> №8 - AIM TRAINING DEVICE | B18: 24-09-22 11:48:38
A20: Average time drift overall: | P20: Interval average:
A21: =AVERAGE(K3, K27, K51, K75, K99, K123, K147, K181) -> 0.0057112146 | P21: =AVERAGE(N3:N250) -> 0.51014431
A23: Average ppm:
A24: =A21 / 3600 * 1000000 -> 1.5864485
D25: =("№"&B4&" - "&A4) -> №3 - ACCZERO PBRC
A26: CALM: | B26: CALP: | D26: Actual time | E26: Device time | F26: Interval | G26: Time drift (s) | H26: Time elapsed minutes | I26: Time drift per hour (with ms) | J26: Time drift per hour | K26: Average error (with ms) | L26: Average error (s/hr) | M26: Time from start (minutes)
A27: =IF(A24 > 0, ROUND(A24 / 0.9537, 0), IF(A24 + 488.5 > 0, ROUND((A24 + 488.5) / 0.9537, 0), 0)) -> 2 | B27: =IF(A24 > 0, 0, 1) -> 0 | D27: 2024-09-22 01:13:23.188910 | E27: 2024-09-22 01:13:22.992686 | F27: [0.188910, 0.203537] | G27: =(DATEVALUE(LEFT(E27, 10))-DATEVALUE(LEFT(D27, 10))) * 86400 + (TIMEVALUE(MID(E27, 12, 8)) - TIMEVALUE(MID(D27, 12, 8))) * 86400 + (VALUE(RIGHT(E27, 6)) - VALUE(RIGHT(D27, 6))) / 1000000 -> -0.196224 | K27: {=((LOOKUP(2,1/(G27:G48<>""),G27:G48) - G27)/SUM(H28:H49)) * 60} -> -0.047342906 | L27: =((FLOOR(MAX(G27:G49), 1)-FLOOR(MIN(G27:G49), 1))/SUM(H28:H49)) * 60 -> 0.048645379 | M27: 0 | N27: =(MID(F27, 2, 7) + MID(F27, 12, 8)) / 2 -> 0.1962235
D28: 2024-09-22 12:21:48.688884 | E28: 2024-09-22 12:21:47.992722 | F28: [0.688884, 0.703439] | G28: =(DATEVALUE(LEFT(E28, 10))-DATEVALUE(LEFT(D28, 10))) * 86400 + (TIMEVALUE(MID(E28, 12, 8)) - TIMEVALUE(MID(D28, 12, 8))) * 86400 + (VALUE(RIGHT(E28, 6)) - VALUE(RIGHT(D28, 6))) / 1000000 -> -0.696162 | H28: =((DATEVALUE(LEFT(D28,10))-DATEVALUE(LEFT(D27,10)))*86400+(TIMEVALUE(MID(D28,12,8))-TIMEVALUE(MID(D27,12,8)))*86400+(VALUE(RIGHT(D28,6))-VALUE(RIGHT(D27,6)))/1000000)/ 60 -> 668.425 | I28: =3600 * (G28-G27) / ((DATEVALUE(LEFT(D28, 10))-DATEVALUE(LEFT(D27, 10))) * 86400 + (TIMEVALUE(MID(D28, 12, 8)) - TIMEVALUE(MID(D27, 12, 8))) * 86400 + (VALUE(RIGHT(D28, 6)) - VALUE(RIGHT(D27, 6))) / 1000000) -> -0.044876059 | J28: =(FLOOR(G28, 1) - FLOOR(G27, 1)) / H28 * 60 -> 0 | M28: =M27 + H28 -> 668.425 | N28: =(MID(F28, 2, 7) + MID(F28, 12, 8)) / 2 -> 0.6961595
D29: 2024-09-22 18:21:16.906693 | E29: 2024-09-22 18:21:15.991958 | F29: [0.906693, 0.922776] | G29: =(DATEVALUE(LEFT(E29, 10))-DATEVALUE(LEFT(D29, 10))) * 86400 + (TIMEVALUE(MID(E29, 12, 8)) - TIMEVALUE(MID(D29, 12, 8))) * 86400 + (VALUE(RIGHT(E29, 6)) - VALUE(RIGHT(D29, 6))) / 1000000 -> -0.914735 | H29: =((DATEVALUE(LEFT(D29,10))-DATEVALUE(LEFT(D28,10)))*86400+(TIMEVALUE(MID(D29,12,8))-TIMEVALUE(MID(D28,12,8)))*86400+(VALUE(RIGHT(D29,6))-VALUE(RIGHT(D28,6)))/1000000)/ 60 -> 359.4703 | I29: =3600 * (G29-G28) / ((DATEVALUE(LEFT(D29, 10))-DATEVALUE(LEFT(D28, 10))) * 86400 + (TIMEVALUE(MID(D29, 12, 8)) - TIMEVALUE(MID(D28, 12, 8))) * 86400 + (VALUE(RIGHT(D29, 6)) - VALUE(RIGHT(D28, 6))) / 1000000) -> -0.036482514 | J29: =(FLOOR(G29, 1) - FLOOR(G28, 1)) / H29 * 60 -> 0 | K29: Average with time set | M29: =M28 + H29 -> 1027.8953 | N29: =(MID(F29, 2, 7) + MID(F29, 12, 8)) / 2 -> 0.914733
D30: 2024-09-23 10:14:04.000387 | E30: 2024-09-23 10:14:02.992032 | F30: [0.000387, 0.016322] | G30: =(DATEVALUE(LEFT(E30, 10))-DATEVALUE(LEFT(D30, 10))) * 86400 + (TIMEVALUE(MID(E30, 12, 8)) - TIMEVALUE(MID(D30, 12, 8))) * 86400 + (VALUE(RIGHT(E30, 6)) - VALUE(RIGHT(D30, 6))) / 1000000 -> -1.008355 | H30: =((DATEVALUE(LEFT(D30,10))-DATEVALUE(LEFT(D29,10)))*86400+(TIMEVALUE(MID(D30,12,8))-TIMEVALUE(MID(D29,12,8)))*86400+(VALUE(RIGHT(D30,6))-VALUE(RIGHT(D29,6)))/1000000)/ 60 -> 952.78489 | I30: =3600 * (G30-G29) / ((DATEVALUE(LEFT(D30, 10))-DATEVALUE(LEFT(D29, 10))) * 86400 + (TIMEVALUE(MID(D30, 12, 8)) - TIMEVALUE(MID(D29, 12, 8))) * 86400 + (VALUE(RIGHT(D30, 6)) - VALUE(RIGHT(D29, 6))) / 1000000) -> -0.0058955595 | J30: =(FLOOR(G30, 1) - FLOOR(G29, 1)) / H30 * 60 -> -0.062973291 | K30: =(MAX(G27:G49) / (DATEDIF(VALUE(DATE(2000 + MID(B13, 1, 2), MID(B13, 4, 2), MID(B13, 7, 2))), VALUE(DATEVALUE(MID(D27, 1, 10)) + TIMEVALUE(MID(D27, 12, 8)) + MID(D27, 21, 6) / 86400000), "d") * 1440 + (TIMEVALUE(MID(D27, 12, 8)) - TIMEVALUE(RIGHT(B13, 8))) * 1440 + MID(D27, 21, 6) / 86400000 + MAX(M27:M49))) * 60 -> -0.0013632375 | M30: =M29 + H30 -> 1980.6802 | N30: =(MID(F30, 2, 7) + MID(F30, 12, 8)) / 2 -> 0.008351
D31: 2024-09-23 13:37:16.125536 | E31: 2024-09-23 13:37:14.992338 | F31: [0.141759, 0.156480] | G31: =(DATEVALUE(LEFT(E31, 10))-DATEVALUE(LEFT(D31, 10))) * 86400 + (TIMEVALUE(MID(E31, 12, 8)) - TIMEVALUE(MID(D31, 12, 8))) * 86400 + (VALUE(RIGHT(E31, 6)) - VALUE(RIGHT(D31, 6))) / 1000000 -> -1.133198 | H31: =((DATEVALUE(LEFT(D31,10))-DATEVALUE(LEFT(D30,10)))*86400+(TIMEVALUE(MID(D31,12,8))-TIMEVALUE(MID(D30,12,8)))*86400+(VALUE(RIGHT(D31,6))-VALUE(RIGHT(D30,6)))/1000000)/ 60 -> 203.20209 | I31: =3600 * (G31-G30) / ((DATEVALUE(LEFT(D31, 10))-DATEVALUE(LEFT(D30, 10))) * 86400 + (TIMEVALUE(MID(D31, 12, 8)) - TIMEVALUE(MID(D30, 12, 8))) * 86400 + (VALUE(RIGHT(D31, 6)) - VALUE(RIGHT(D30, 6))) / 1000000) -> -0.036862712 | J31: =(FLOOR(G31, 1) - FLOOR(G30, 1)) / H31 * 60 -> 0 | M31: =M30 + H31 -> 2183.8823 | N31: =(MID(F31, 2, 7) + MID(F31, 12, 8)) / 2 -> 0.149115
D32: 2024-09-24 00:09:45.781820 | E32: 2024-09-24 00:09:42.992291 | F32: [0.797085, 0.812983] | G32: =(DATEVALUE(LEFT(E32, 10))-DATEVALUE(LEFT(D32, 10))) * 86400 + (TIMEVALUE(MID(E32, 12, 8)) - TIMEVALUE(MID(D32, 12, 8))) * 86400 + (VALUE(RIGHT(E32, 6)) - VALUE(RIGHT(D32, 6))) / 1000000 -> -2.789529 | H32: =((DATEVALUE(LEFT(D32,10))-DATEVALUE(LEFT(D31,10)))*86400+(TIMEVALUE(MID(D32,12,8))-TIMEVALUE(MID(D31,12,8)))*86400+(VALUE(RIGHT(D32,6))-VALUE(RIGHT(D31,6)))/1000000)/ 60 -> 632.49427 | I32: =3600 * (G32-G31) / ((DATEVALUE(LEFT(D32, 10))-DATEVALUE(LEFT(D31, 10))) * 86400 + (TIMEVALUE(MID(D32, 12, 8)) - TIMEVALUE(MID(D31, 12, 8))) * 86400 + (VALUE(RIGHT(D32, 6)) - VALUE(RIGHT(D31, 6))) / 1000000) -> -0.15712373 | J32: =(FLOOR(G32, 1) - FLOOR(G31, 1)) / H32 * 60 -> -0.094862519 | K32: Standard Deviation | M32: =M31 + H32 -> 2816.3765 | N32: =(MID(F32, 2, 7) + MID(F32, 12, 8)) / 2 -> 0.8050315
D33: 2024-09-24 11:07:31.313181 | E33: 2024-09-24 11:07:27.992356 | F33: [0.313181, 0.328468] | G33: =(DATEVALUE(LEFT(E33, 10))-DATEVALUE(LEFT(D33, 10))) * 86400 + (TIMEVALUE(MID(E33, 12, 8)) - TIMEVALUE(MID(D33, 12, 8))) * 86400 + (VALUE(RIGHT(E33, 6)) - VALUE(RIGHT(D33, 6))) / 1000000 -> -3.320825 | H33: =((DATEVALUE(LEFT(D33,10))-DATEVALUE(LEFT(D32,10)))*86400+(TIMEVALUE(MID(D33,12,8))-TIMEVALUE(MID(D32,12,8)))*86400+(VALUE(RIGHT(D33,6))-VALUE(RIGHT(D32,6)))/1000000)/ 60 -> 657.75886 | I33: =3600 * (G33-G32) / ((DATEVALUE(LEFT(D33, 10))-DATEVALUE(LEFT(D32, 10))) * 86400 + (TIMEVALUE(MID(D33, 12, 8)) - TIMEVALUE(MID(D32, 12, 8))) * 86400 + (VALUE(RIGHT(D33, 6)) - VALUE(RIGHT(D32, 6))) / 1000000) -> -0.048464205 | J33: =(FLOOR(G33, 1) - FLOOR(G32, 1)) / H33 * 60 -> -0.09121884 | K33: =_xlfn.STDEV.P(I28:I48) -> 0.033241388 | M33: =M32 + H33 -> 3474.1354 | N33: =(MID(F33, 2, 7) + MID(F33, 12, 8)) / 2 -> 0.320824
D34: 2024-09-25 00:50:15.844560 | E34: 2024-09-25 00:50:11.992404 | F34: [0.844560, 0.859752] | G34: =(DATEVALUE(LEFT(E34, 10))-DATEVALUE(LEFT(D34, 10))) * 86400 + (TIMEVALUE(MID(E34, 12, 8)) - TIMEVALUE(MID(D34, 12, 8))) * 86400 + (VALUE(RIGHT(E34, 6)) - VALUE(RIGHT(D34, 6))) / 1000000 -> -3.852156 | H34: =((DATEVALUE(LEFT(D34,10))-DATEVALUE(LEFT(D33,10)))*86400+(TIMEVALUE(MID(D34,12,8))-TIMEVALUE(MID(D33,12,8)))*86400+(VALUE(RIGHT(D34,6))-VALUE(RIGHT(D33,6)))/1000000)/ 60 -> 822.74219 | I34: =3600 * (G34-G33) / ((DATEVALUE(LEFT(D34, 10))-DATEVALUE(LEFT(D33, 10))) * 86400 + (TIMEVALUE(MID(D34, 12, 8)) - TIMEVALUE(MID(D33, 12, 8))) * 86400 + (VALUE(RIGHT(D34, 6)) - VALUE(RIGHT(D33, 6))) / 1000000) -> -0.038748299 | J34: =(FLOOR(G34, 1) - FLOOR(G33, 1)) / H34 * 60 -> 0 | M34: =M33 + H34 -> 4296.8776 | N34: =(MID(F34, 2, 7) + MID(F34, 12, 8)) / 2 -> 0.852156
D35: 2024-09-25 11:50:57.344451 | E35: 2024-09-25 11:50:52.992082 | F35: [0.360919, 0.376295] | G35: =(DATEVALUE(LEFT(E35, 10))-DATEVALUE(LEFT(D35, 10))) * 86400 + (TIMEVALUE(MID(E35, 12, 8)) - TIMEVALUE(MID(D35, 12, 8))) * 86400 + (VALUE(RIGHT(E35, 6)) - VALUE(RIGHT(D35, 6))) / 1000000 -> -4.352369 | H35: =((DATEVALUE(LEFT(D35,10))-DATEVALUE(LEFT(D34,10)))*86400+(TIMEVALUE(MID(D35,12,8))-TIMEVALUE(MID(D34,12,8)))*86400+(VALUE(RIGHT(D35,6))-VALUE(RIGHT(D34,6)))/1000000)/ 60 -> 660.69166 | I35: =3600 * (G35-G34) / ((DATEVALUE(LEFT(D35, 10))-DATEVALUE(LEFT(D34, 10))) * 86400 + (TIMEVALUE(MID(D35, 12, 8)) - TIMEVALUE(MID(D34, 12, 8))) * 86400 + (VALUE(RIGHT(D35, 6)) - VALUE(RIGHT(D34, 6))) / 1000000) -> -0.045426303 | J35: =(FLOOR(G35, 1) - FLOOR(G34, 1)) / H35 * 60 -> -0.09081392 | M35: =M34 + H35 -> 4957.5693 | N35: =(MID(F35, 2, 7) + MID(F35, 12, 8)) / 2 -> 0.3686025
D36: 2024-09-25 23:47:42.875549 | E36: 2024-09-25 23:47:37.992259 | F36: [0.875549, 0.891031] | G36: =(DATEVALUE(LEFT(E36, 10))-DATEVALUE(LEFT(D36, 10))) * 86400 + (TIMEVALUE(MID(E36, 12, 8)) - TIMEVALUE(MID(D36, 12, 8))) * 86400 + (VALUE(RIGHT(E36, 6)) - VALUE(RIGHT(D36, 6))) / 1000000 -> -4.88329 | H36: =((DATEVALUE(LEFT(D36,10))-DATEVALUE(LEFT(D35,10)))*86400+(TIMEVALUE(MID(D36,12,8))-TIMEVALUE(MID(D35,12,8)))*86400+(VALUE(RIGHT(D36,6))-VALUE(RIGHT(D35,6)))/1000000)/ 60 -> 716.75885 | I36: =3600 * (G36-G35) / ((DATEVALUE(LEFT(D36, 10))-DATEVALUE(LEFT(D35, 10))) * 86400 + (TIMEVALUE(MID(D36, 12, 8)) - TIMEVALUE(MID(D35, 12, 8))) * 86400 + (VALUE(RIGHT(D36, 6)) - VALUE(RIGHT(D35, 6))) / 1000000) -> -0.044443483 | J36: =(FLOOR(G36, 1) - FLOOR(G35, 1)) / H36 * 60 -> 0 | M36: =M35 + H36 -> 5674.3281 | N36: =(MID(F36, 2, 7) + MID(F36, 12, 8)) / 2 -> 0.8832855
D37: 2024-09-26 18:03:49.657063 | E37: 2024-09-26 18:03:43.992096 | F37: [0.673573, 0.687732] | G37: =(DATEVALUE(LEFT(E37, 10))-DATEVALUE(LEFT(D37, 10))) * 86400 + (TIMEVALUE(MID(E37, 12, 8)) - TIMEVALUE(MID(D37, 12, 8))) * 86400 + (VALUE(RIGHT(E37, 6)) - VALUE(RIGHT(D37, 6))) / 1000000 -> -5.664967 | H37: =((DATEVALUE(LEFT(D37,10))-DATEVALUE(LEFT(D36,10)))*86400+(TIMEVALUE(MID(D37,12,8))-TIMEVALUE(MID(D36,12,8)))*86400+(VALUE(RIGHT(D37,6))-VALUE(RIGHT(D36,6)))/1000000)/ 60 -> 1096.113 | I37: =3600 * (G37-G36) / ((DATEVALUE(LEFT(D37, 10))-DATEVALUE(LEFT(D36, 10))) * 86400 + (TIMEVALUE(MID(D37, 12, 8)) - TIMEVALUE(MID(D36, 12, 8))) * 86400 + (VALUE(RIGHT(D37, 6)) - VALUE(RIGHT(D36, 6))) / 1000000) -> -0.042788124 | J37: =(FLOOR(G37, 1) - FLOOR(G36, 1)) / H37 * 60 -> -0.054738881 | M37: =M36 + H37 -> 6770.4411 | N37: =(MID(F37, 2, 7) + MID(F37, 12, 8)) / 2 -> 0.680651
D38: 2024-09-27 02:09:31.969770 | E38: 2024-09-27 02:09:25.992371 | F38: [0.969770, 0.985028] | G38: =(DATEVALUE(LEFT(E38, 10))-DATEVALUE(LEFT(D38, 10))) * 86400 + (TIMEVALUE(MID(E38, 12, 8)) - TIMEVALUE(MID(D38, 12, 8))) * 86400 + (VALUE(RIGHT(E38, 6)) - VALUE(RIGHT(D38, 6))) / 1000000 -> -5.977399 | H38: =((DATEVALUE(LEFT(D38,10))-DATEVALUE(LEFT(D37,10)))*86400+(TIMEVALUE(MID(D38,12,8))-TIMEVALUE(MID(D37,12,8)))*86400+(VALUE(RIGHT(D38,6))-VALUE(RIGHT(D37,6)))/1000000)/ 60 -> 485.70521 | I38: =3600 * (G38-G37) / ((DATEVALUE(LEFT(D38, 10))-DATEVALUE(LEFT(D37, 10))) * 86400 + (TIMEVALUE(MID(D38, 12, 8)) - TIMEVALUE(MID(D37, 12, 8))) * 86400 + (VALUE(RIGHT(D38, 6)) - VALUE(RIGHT(D37, 6))) / 1000000) -> -0.038595262 | J38: =(FLOOR(G38, 1) - FLOOR(G37, 1)) / H38 * 60 -> 0 | M38: =M37 + H38 -> 7256.1463 | N38: =(MID(F38, 2, 7) + MID(F38, 12, 8)) / 2 -> 0.977399
D39: 2024-09-27 12:11:22.532024 | E39: 2024-09-27 12:11:15.992473 | F39: [0.548146, 0.563044] | G39: =(DATEVALUE(LEFT(E39, 10))-DATEVALUE(LEFT(D39, 10))) * 86400 + (TIMEVALUE(MID(E39, 12, 8)) - TIMEVALUE(MID(D39, 12, 8))) * 86400 + (VALUE(RIGHT(E39, 6)) - VALUE(RIGHT(D39, 6))) / 1000000 -> -6.539551 | H39: =((DATEVALUE(LEFT(D39,10))-DATEVALUE(LEFT(D38,10)))*86400+(TIMEVALUE(MID(D39,12,8))-TIMEVALUE(MID(D38,12,8)))*86400+(VALUE(RIGHT(D39,6))-VALUE(RIGHT(D38,6)))/1000000)/ 60 -> 601.8427 | I39: =3600 * (G39-G38) / ((DATEVALUE(LEFT(D39, 10))-DATEVALUE(LEFT(D38, 10))) * 86400 + (TIMEVALUE(MID(D39, 12, 8)) - TIMEVALUE(MID(D38, 12, 8))) * 86400 + (VALUE(RIGHT(D39, 6)) - VALUE(RIGHT(D38, 6))) / 1000000) -> -0.056043082 | J39: =(FLOOR(G39, 1) - FLOOR(G38, 1)) / H39 * 60 -> -0.099693823 | M39: =M38 + H39 -> 7857.9891 | N39: =(MID(F39, 2, 7) + MID(F39, 12, 8)) / 2 -> 0.555592
D40: 2024-09-28 01:07:18.001545 | E40: 2024-09-28 01:07:10.992745 | F40: [0.016493, 0.031525] | G40: =(DATEVALUE(LEFT(E40, 10))-DATEVALUE(LEFT(D40, 10))) * 86400 + (TIMEVALUE(MID(E40, 12, 8)) - TIMEVALUE(MID(D40, 12, 8))) * 86400 + (VALUE(RIGHT(E40, 6)) - VALUE(RIGHT(D40, 6))) / 1000000 -> -7.0088 | H40: =((DATEVALUE(LEFT(D40,10))-DATEVALUE(LEFT(D39,10)))*86400+(TIMEVALUE(MID(D40,12,8))-TIMEVALUE(MID(D39,12,8)))*86400+(VALUE(RIGHT(D40,6))-VALUE(RIGHT(D39,6)))/1000000)/ 60 -> 775.92449 | I40: =3600 * (G40-G39) / ((DATEVALUE(LEFT(D40, 10))-DATEVALUE(LEFT(D39, 10))) * 86400 + (TIMEVALUE(MID(D40, 12, 8)) - TIMEVALUE(MID(D39, 12, 8))) * 86400 + (VALUE(RIGHT(D40, 6)) - VALUE(RIGHT(D39, 6))) / 1000000) -> -0.03628567 | J40: =(FLOOR(G40, 1) - FLOOR(G39, 1)) / H40 * 60 -> -0.077327112 | M40: =M39 + H40 -> 8633.9135 | N40: =(MID(F40, 2, 7) + MID(F40, 12, 8)) / 2 -> 0.0240075
D49: =("№"&B5&" - "&A5) -> №4 - IMGCOF
D50: Actual time | E50: Device time | F50: Interval | G50: Time drift (s) | H50: Time elapsed minutes | I50: Time drift per hour (with ms) | J50: Time drift per hour | K50: Average error (with ms) | L50: Average error (s/hr) | M50: Time from start (minutes)
...

Sheet Test1
A1: Device Label | B1: Device № | D1: =("№"&B3&" - "&A3) -> №2 - Blue tape | AO1: {=Test1!N3:N300} -> 0.8208325
